File: 12-1523-950C-02-60s.csv
Time,Force,Jaw,Strain,Stress,TC1
(sec),(kN),(mm),,(MPa),(C)
0,0.25635736999999997,1.0589243999999999E-2,0.000750,3.2198565000000001,950.00043000000005
2.5999999999999999E-2,0.23764893000000001,7.9656643999999992E-3,0.000929,3.0028326999999999,949.86963000000003
5.1999999999999998E-2,0.1340874,6.6700470999999997E-3,0.000931,1.7315334,949.89398000000006
7.8E-2,10.783579,1.4721379999999999,0.13066438999999999,120.38276,950.96325999999999
0.104,10.161557,2.4116673,0.22468763999999999,103.45442,953.37114999999994
0.13,8.5238513999999999,2.4140944000000002,0.22511527000000001,86.675162999999998,952.79778999999996
0.156,7.9904584999999999,2.4160314000000001,0.22527349999999999,81.219887,952.09747000000004
0.182,7.7866220000000004,2.4134951,0.22492607000000001,79.097426999999996,951.98595999999998
0.20799999999999999,7.3617954000000001,2.4159651000000002,0.22515938999999999,74.815246999999999,951.43682999999999
0.23400000000000001,7.1931371999999998,2.4205028999999998,0.22566017999999999,72.977790999999996,951.74181999999996
0.26,7.0598768999999999,2.4126503000000001,0.22482529000000001,72.013007999999999,951.85077000000001
0.28599999999999998,6.8887229000000003,2.4169309000000001,0.22517756999999999,70.012778999999995,951.82012999999995
0.312,6.6640549,2.4134158999999999,0.22481638000000001,67.750488000000004,951.69757000000004
0.33800000000000002,6.7090987999999996,2.4176742999999998,0.22522506,68.187386000000004,951.66876000000002
0.36399999999999999,6.6988691999999999,2.4198754,0.22545554000000001,68.187140999999997,951.22198000000003
0.39,7.3274226000000002,2.4295547000000002,0.22645884999999999,73.122474999999994,951.11658
0.41599999999999998,6.5684104000000003,2.4191220000000002,0.22531232000000001,66.765265999999997,950.90466000000004
0.442,6.8497019000000003,2.4165462999999998,0.22500371999999999,69.589684000000005,950.47442999999998
0.46800000000000003,6.4881263000000002,2.4203291,0.22539164,65.941879,950.35888999999997
0.49399999999999999,6.2761506999999996,2.4213146999999999,0.22548193999999999,63.767059000000003,949.83356000000003
0.52,5.5001582999999998,2.4261401,0.22585653,55.133606,949.75640999999996
0.54600000000000004,6.1919050000000002,2.4195549000000001,0.22521298000000001,62.962864000000003,949.33801000000005
0.57199999999999995,6.1256846999999999,2.4170791999999999,0.22485996999999999,62.216605999999999,948.80713000000003
0.59799999999999998,6.1542158000000002,2.4197438,0.2252644,62.563934000000003,948.28063999999995
0.624,6.092536,2.4204013,0.22532541,61.903056999999997,948.14873999999998
0.65,6.5857390999999996,2.4324286000000002,0.22653534,67.431297000000001,947.55902000000003
0.67600000000000005,6.0730070999999999,2.4201161999999998,0.22524511999999999,61.767727000000001,946.72204999999997
0.70199999999999996,6.3412724000000003,2.4200678,0.22522758000000001,64.367797999999993,946.60107000000005
0.72799999999999998,6.0624652000000001,2.4207141000000001,0.22531857999999999,61.588833000000001,945.86181999999997
0.754,5.9642476999999996,2.4230293999999999,0.22552320000000001,60.604560999999997,945.65607
0.78,5.7688651000000002,2.4318472999999998,0.22641991,57.962566000000002,945.20470999999998
0.80600000000000005,5.9728874999999997,2.4211472999999999,0.22526634000000001,60.706493000000002,944.39764000000002
0.83199999999999996,5.8217772999999999,2.4230849999999999,0.22541765999999999,59.219512999999999,944.21465999999998
0.85799999999999998,5.9259443000000003,2.4220394999999999,0.22538654999999999,60.233994000000003,944.00787000000003
0.88400000000000001,5.9268131000000004,2.4226296,0.22537144000000001,60.220981999999999,943.71014000000002
0.91,5.9944921000000004,2.4313679000000001,0.22627365999999999,61.166378000000002,943.14892999999995
0.93600000000000005,5.9400477,2.4228282000000001,0.22538505,60.431750999999998,942.45989999999995
0.96199999999999997,6.2970777,2.4272763999999998,0.22573534000000001,63.987003000000001,942.33099000000004
0.98799999999999999,5.9786954000000003,2.4236361999999998,0.22534513,60.799965,941.96691999999996
1.014,6.0481705999999997,2.4248352,0.22546126999999999,61.40699,941.41021999999998
1.04,5.9827490000000001,2.4267430000000001,0.22572875000000001,60.550102000000003,941.77521000000002
1.0660000000000001,5.8859110000000001,2.4247529999999999,0.22548570000000001,59.834102999999999,941.31604000000004
1.0920000000000001,5.8085141,2.4291632000000001,0.22590925000000001,59.011634999999998,940.97924999999998
1.1180000000000001,5.9023174999999997,2.4422063999999999,0.22699916000000001,59.928916999999998,940.73712
1.1439999999999999,5.9427608999999997,2.4257298,0.22556427000000001,60.376789000000002,940.58856000000003
1.17,5.7882414000000004,2.4234116000000001,0.22537789,59.056888999999998,940.29462000000001
1.196,5.8930239999999996,2.4273962999999998,0.22558217999999999,59.838656999999998,940.16485999999998
1.222,6.2387743000000002,2.4333279000000001,0.22628523,63.314259,939.87145999999996
1.248,6.6054501999999999,2.4444625000000002,0.22760136,64.457252999999994,939.55322000000001
1.274,5.8645597,2.4271506999999999,0.22566748,59.588721999999997,939.91588999999999
1.3,6.0813664999999997,2.4230548999999999,0.22532063999999999,61.707977,939.71172999999999
1.3260000000000001,5.864007,2.4269797999999998,0.22566723999999999,59.575733,939.87878000000001
1.3520000000000001,5.6338615000000001,2.4350779,0.22641744999999999,56.834209000000001,939.83965999999998
1.3779999999999999,4.7731399999999997,2.4440472,0.22739229,48.017719,939.76464999999996
1.4039999999999999,5.7816944000000001,2.4272171999999999,0.22572283000000001,58.770553999999997,939.43877999999995
1.43,5.6120491000000001,2.4193220000000002,0.2249428,57.100715999999998,939.83459000000005
1.456,5.6720281000000004,2.4279842,0.22572413,57.615741999999997,939.64428999999996
1.482,5.9444021999999999,2.4350885999999998,0.22651526,60.628799000000001,940.02155000000005
1.508,6.5995511999999996,2.4395796999999999,0.22694199000000001,67.267204000000007,939.91454999999996
1.534,5.8282175000000001,2.4289752999999998,0.22601883,59.222487999999998,939.85735999999997
1.56,5.9313126,2.4223026999999999,0.22525734,60.174095000000001,940.33001999999999
1.5860000000000001,5.6524166999999998,2.4287535999999998,0.22604415999999999,57.426918000000001,940.20758000000001
1.6120000000000001,5.6627144999999999,2.4344320000000002,0.22664876,57.492919999999998,940.39111000000003
1.6379999999999999,4.9387236000000003,2.4372573000000002,0.22694616000000001,50.120316000000003,940.43793000000005
1.6639999999999999,5.6166682000000003,2.4268041,0.22598573999999999,57.092708999999999,940.43322999999998
1.69,5.4543233000000004,2.4170508000000002,0.22493411999999999,55.481490999999998,940.69628999999998
1.716,5.5212336000000004,2.4275422,0.22604552,56.117480999999998,941.04169000000002
1.742,5.5884628000000003,2.4347286000000001,0.22692592,56.826191000000001,940.93047999999999
1.768,6.0681858000000002,2.4450614000000002,0.22801295999999999,62.034869999999998,941.20061999999996
1.794,5.5131268999999996,2.4273145,0.22610293000000001,56.024020999999998,941.67938000000004
1.82,5.6673974999999999,2.4202708999999998,0.22534828000000001,57.559466999999998,941.64917000000003
1.8460000000000001,5.4776892999999998,2.4272325000000001,0.22623312000000001,55.619948999999998,942.10564999999997
1.8720000000000001,5.5142230999999997,2.4341588000000001,0.22700733000000001,55.9557,941.93079
1.8979999999999999,5.0020251,2.4410162,0.22759387,50.392479000000002,942.18073000000004
1.9239999999999999,5.3584328000000001,2.426358,0.22621040000000001,54.418888000000003,942.61383000000001
1.95,5.3971080999999996,2.4192605,0.22544687999999999,54.874836000000002,942.53394000000003
1.976,5.3012395000000003,2.4267983000000002,0.22626178999999999,53.850135999999999,942.70087000000001
2.0019999999999998,5.2669968999999996,2.4309587000000001,0.22676413000000001,53.415798000000002,942.64148
2.028,5.4811095999999999,2.4411372999999998,0.22796255000000001,55.837851999999998,943.31084999999996
2.0539999999999998,5.2378764000000002,2.4255618999999999,0.22617513,53.179371000000003,943.48015999999996
2.08,5.3818263999999996,2.4231343000000001,0.22576537999999999,54.704388000000002,944.03521999999998
2.1059999999999999,5.2036623999999998,2.424865,0.22608992,52.840846999999997,943.98572000000001
2.1320000000000001,5.3137388000000003,2.4309337000000002,0.22673635,53.901195999999999,944.43646000000001
2.1579999999999999,4.8988389999999997,2.4384301000000002,0.22750576,49.443741000000003,944.65746999999999
2.1840000000000002,5.1594943999999998,2.4257615000000001,0.22620355,52.370975000000001,944.28278
2.21,5.0156159000000002,2.4231593999999999,0.22574089,50.953460999999997,944.71227999999996
2.2360000000000002,5.0177965000000002,2.426825,0.22626224,50.982883000000001,944.72637999999995
2.262,5.0351710000000001,2.4290284999999998,0.22649361000000001,51.123634000000003,945.00158999999996
2.2879999999999998,5.2134657000000004,2.4374110999999998,0.22736856,53.034691000000002,945.23468000000003
2.3140000000000001,4.9756140999999996,2.4258253999999999,0.22601210999999999,50.522258999999998,945.99816999999996
2.34,5.0096654999999997,2.4275999000000001,0.22619740999999999,50.806046000000002,945.58965999999998
2.3660000000000001,4.8097162000000004,2.4255292000000002,0.22592533000000001,48.837685,945.93236999999999
2.3919999999999999,4.9230432999999998,2.4289689000000001,0.22631709,50.061081000000001,946.35222999999996
2.4180000000000001,4.7906646999999998,2.4346619,0.22691380999999999,48.418838999999998,945.98784999999998
2.444,4.7355565999999998,2.4252821999999998,0.22583111,48.109046999999997,946.08025999999995
2.4700000000000002,4.6632756999999998,2.4276178000000002,0.22597726000000001,47.395809,945.90111999999999
2.496,4.8051294999999996,2.4267615999999999,0.22588035000000001,48.805222000000001,946.49158
2.5219999999999998,4.6618671000000003,2.4274138999999999,0.22604753,47.322651,946.20581000000004
2.548,4.7126875000000004,2.4310874999999998,0.22653440999999999,47.975121000000001,947.03936999999996
2.5739999999999998,4.6115208000000001,2.4267180000000002,0.22587568999999999,46.875191000000001,946.88604999999995
2.6,4.7567978000000002,2.4335505999999998,0.22646761000000001,48.331940000000003,946.88409000000001
2.6259999999999999,4.6054048999999999,2.4243351999999998,0.22574957000000001,46.843525,947.29241999999999
2.6520000000000001,4.5543122,2.4285827000000002,0.22606888,46.277270999999999,947.17724999999996
2.6779999999999999,4.6437435000000002,2.4290812000000002,0.22630140000000001,47.106051999999998,947.34540000000004
2.7040000000000002,4.5553850999999996,2.4268345999999998,0.22583035000000001,46.229187000000003,946.81335000000001
2.73,4.4839520000000004,2.4313362000000001,0.22629346,45.578617000000001,947.36217999999997
2.7559999999999998,4.5402570000000004,2.4425284999999999,0.22733233999999999,46.301605000000002,947.57390999999996
2.782,4.4707508000000002,2.4282748999999999,0.22593519000000001,45.356583000000001,946.90008999999998
2.8079999999999998,4.5141138999999999,2.4251573,0.22573799,45.876700999999997,947.59118999999998
2.8340000000000001,4.4548993000000001,2.4287968000000002,0.22598140999999999,45.206099999999999,947.84942999999998
2.86,4.4083433000000003,2.4374425,0.22678651999999999,45.055999999999997,948.01415999999995
2.8860000000000001,4.7977109000000002,2.4278735999999999,0.22571558999999999,46.986378000000002,947.90552000000002
2.9119999999999999,4.3057013,2.4293847,0.22606944000000001,43.742232999999999,948.24854000000005
2.9380000000000002,4.4184251000000003,2.4233201000000002,0.22544138,44.801952,947.74603000000002
2.964,4.3399587000000004,2.4298109999999999,0.22598857,44.073425,948.07024999999999
2.99,4.4435000000000002,2.4392773999999999,0.22694902,44.977505000000001,948.22637999999995
3.016,3.6039162,2.4390132000000002,0.22682774,36.785919,947.99036000000001
3.0419999999999998,4.3018336000000001,2.4310513,0.22606799,43.698802999999998,948.19237999999996
3.0680000000000001,4.2011428000000004,2.4208772000000001,0.22510545000000001,42.667664000000002,948.30023000000006
3.0939999999999999,4.1883540000000004,2.4312623000000002,0.226074,42.528851000000003,948.52008000000001
3.12,4.2031821999999996,2.4397533,0.22699881999999999,42.6297,948.52941999999996
3.1459999999999999,4.7115492999999997,2.4443378,0.22729579,48.489635,948.65593999999999
3.1720000000000002,4.2856097000000002,2.4326837000000001,0.22617098999999999,43.546429000000003,948.48694
3.198,4.4218916999999998,2.4238384000000002,0.22532061,45.005104000000003,948.56579999999997
3.2240000000000002,4.2623825000000002,2.4318469,0.2260894,43.285732000000003,948.67456000000004
3.25,4.2513493999999996,2.4403830000000002,0.22702934,43.026046999999998,948.41467
3.2759999999999998,3.6335926000000001,2.4387810000000001,0.22676028000000001,36.958618000000001,948.71954000000005
3.302,4.0574903000000004,2.4331841000000001,0.22628713,41.198760999999998,948.48779000000002
3.3279999999999998,4.0997705,2.4229069000000001,0.22521740000000001,41.626587000000001,948.79516999999998
3.3540000000000001,4.1098923999999997,2.4334533,0.22636398999999999,41.733688000000001,948.90570000000002
3.38,3.9694343000000001,2.4407570000000001,0.22718135,40.300694,948.61121000000003
3.4060000000000001,4.4780449999999998,2.4506865000000002,0.22817703,45.644455000000001,948.89160000000004
3.4319999999999999,4.0104156,2.4333917999999999,0.22638643,40.698193000000003,949.24883999999997
3.4580000000000002,4.1273970999999996,2.4262172999999998,0.22562989999999999,41.918346,948.93591000000004
3.484,3.9551327000000001,2.4324995999999999,0.22638722,40.137824999999999,948.85253999999998
3.51,4.0550484999999998,2.4387479000000001,0.22706717000000001,41.142978999999997,948.89868000000001
3.536,3.6186001000000001,2.4456069,0.22781905999999999,36.232506000000001,948.70874000000003
3.5619999999999998,3.9703852999999998,2.4315590999999999,0.22642340999999999,40.276744999999998,948.98206000000005
3.5880000000000001,4.0183086000000001,2.4246420999999998,0.22564329,40.837814000000002,948.83978000000002
3.6139999999999999,3.9650403999999999,2.4322493000000001,0.22653377,40.251209000000003,948.77881000000002
3.64,3.9861879,2.4367497,0.22708962999999999,40.389709000000003,949.13342
3.6659999999999999,4.1659306999999997,2.4474412999999999,0.22827549,42.503608999999997,949.08709999999996
3.6920000000000002,3.9056578000000002,2.4318886000000002,0.22664601000000001,39.649548000000003,949.31389999999999
3.718,3.9784826999999998,2.4291152999999999,0.22616388000000001,40.481498999999999,949.22400000000005
3.7440000000000002,3.9068539000000002,2.4313197,0.22667325999999999,39.661861000000002,949.15002000000004
3.77,3.992038,2.4350231,0.22717775000000001,40.557476000000001,948.72893999999997
3.7959999999999998,3.7640728999999999,2.4438281000000002,0.22805747000000001,37.835312000000002,949.16558999999995
3.8220000000000001,3.9597148999999998,2.4295015000000002,0.22653496000000001,40.166027,948.92687999999998
3.8479999999999999,3.760335,2.4277451000000001,0.22634468999999999,38.144440000000003,948.80773999999997
3.8740000000000001,3.819016,2.4303159999999999,0.22660085999999999,38.770389999999999,949.23969
3.9,3.7863376,2.4317283999999999,0.22685991,38.418125000000003,949.20532000000003
3.9260000000000002,3.8184786000000002,2.4405320000000001,0.22788109000000001,38.951534000000002,949.43413999999996
3.952,3.7835393000000002,2.4290581000000002,0.22646372000000001,38.384129000000001,949.38244999999995
3.9780000000000002,3.9300405999999999,2.4322974999999998,0.22676453999999999,39.920959000000003,949.41876000000002
4.0039999999999996,3.7264046999999998,2.4287657999999999,0.22648709,37.833565,948.89599999999996
4.03,3.775655,2.4314480000000001,0.22682366000000001,38.362983999999997,949.14702999999997
4.056,3.6923499,2.4376967,0.22752169,37.290089000000002,949.28612999999996
4.0819999999999999,3.6498352999999999,2.4287337999999998,0.22642372999999999,37.004111999999999,948.70117000000005
4.1079999999999997,3.6670834999999999,2.4331326,0.22673076,37.184863999999997,949.29974000000004
4.1340000000000003,3.6761130999999998,2.4298375000000001,0.22651777000000001,37.335903000000002,949.33861999999999
4.16,3.7133843999999998,2.4297819,0.22653037000000001,37.669842000000003,949.57635000000005
4.1859999999999999,3.7700434,2.4317392999999998,0.22687510999999999,38.302044000000002,949.42193999999995
4.2119999999999997,3.6525561999999998,2.4277896999999999,0.2262644,37.084716999999998,949.45818999999995
4.2380000000000004,3.7925466999999999,2.4350285999999999,0.22699206,38.513759999999998,949.18871999999999
4.2640000000000002,3.6209121,2.4293076999999998,0.22640658999999999,36.936149999999998,949.36072000000001
4.29,3.6191225,2.4291146000000001,0.22634931,36.721969999999999,949.41254000000004
4.3159999999999998,3.6633477000000001,2.4277215000000001,0.22624384,37.112259000000002,949.16552999999999
4.3419999999999996,3.6239607,2.4277300999999998,0.22604099,36.835163000000001,949.34766000000002
4.3680000000000003,3.5973245999999999,2.4345791000000001,0.22671577000000001,36.228909000000002,949.09771999999998
4.3940000000000001,3.1423643000000001,2.4214318000000001,0.22519198000000001,33.527523000000002,949.34087999999997
4.42,3.5377998000000002,2.4286120000000002,0.22615226999999999,35.967857000000002,949.57776000000001
4.4459999999999997,3.4903593000000002,2.4222006999999999,0.22555193000000001,35.471606999999999,949.80273
4.4720000000000004,3.512238,2.4283248999999998,0.22611054999999999,35.676406999999998,949.34906000000001
4.4980000000000002,3.4561633999999999,2.4374842999999999,0.22700203999999999,35.218013999999997,949.44835999999998
4.524,4.2118459000000001,2.4387015999999999,0.22715732,41.910259000000003,949.58185000000003
4.55,3.5607646000000002,2.4300666,0.22612926,36.160870000000003,949.04376000000002
4.5759999999999996,3.6875064000000002,2.4206953000000002,0.22543042999999999,37.471066,949.25995
4.6020000000000003,3.5377181000000002,2.4281050999999998,0.22595987000000001,35.982928999999999,949.44623000000001
4.6280000000000001,3.5589306000000001,2.4370940000000001,0.22693853,36.187182999999997,949.46447999999998
4.6539999999999999,3.0095736999999998,2.4470958999999999,0.22791003000000001,29.692774,949.43439000000001
4.68,3.5331359,2.4288926000000002,0.22604582000000001,35.833075999999998,949.28668000000005
4.7060000000000004,3.4140754000000002,2.4187362000000001,0.22499104,34.632393,949.50194999999997
4.7320000000000002,3.4304530999999998,2.4300480000000002,0.22612245,34.806355000000003,949.58471999999995
4.758,3.4035593999999998,2.4380090000000001,0.22703543000000001,34.589153000000003,949.21087999999997
4.7839999999999998,3.8514178000000001,2.4442995000000001,0.22744484000000001,38.937027,949.41510000000005
4.8099999999999996,3.4429208999999998,2.4316114999999998,0.22621869999999999,35.012298999999999,949.35895000000005
4.8360000000000003,3.5844336000000001,2.4228518000000001,0.22522072000000001,36.448689000000002,949.55529999999999
4.8620000000000001,3.3920300000000001,2.4304423000000002,0.22610050000000001,34.414627000000003,949.53747999999996
4.8879999999999999,3.4962699000000002,2.4376723999999999,0.22683676,35.486725,949.39562999999998
4.9139999999999997,2.8609996,2.4433023999999999,0.22736606000000001,28.761721000000001,949.57190000000003
4.9400000000000004,3.2957835000000002,2.4307021999999998,0.22596857000000001,33.471831999999999,949.81670999999994
4.9660000000000002,3.1953371000000002,2.4219997000000002,0.22509288999999999,32.456558000000001,950.04474000000005
4.992,3.2553399000000001,2.4316005999999999,0.22614877,33.042416000000003,949.58123999999998
5.0179999999999998,3.2434120000000002,2.4373659999999999,0.22672260999999999,32.886974000000002,949.62621999999999
5.0439999999999996,3.6388132999999998,2.448909,0.22789756999999999,37.323180999999998,949.30426
5.07,3.3047944999999999,2.4333434,0.22627132999999999,33.544373,949.48743000000002
5.0960000000000001,3.4075142999999999,2.4290110999999999,0.22570190000000001,34.609413000000004,949.52228000000002
5.1219999999999999,3.2902535999999998,2.4332210999999999,0.22624198000000001,33.415897000000001,950.09283000000005
5.1479999999999997,3.3036034000000001,2.4390562,0.22692917000000001,33.538288000000001,949.72960999999998
5.1740000000000004,3.1267021000000002,2.4473547999999998,0.22773702000000001,31.262664999999998,949.61492999999996
5.2,3.3778858,2.4336509999999998,0.22631429,34.312851000000002,949.46258999999998
5.226,3.2573797999999998,2.4296663000000001,0.22582453,33.031517000000001,949.70965999999999
5.2519999999999998,3.1914041000000002,2.4343840999999999,0.22642972,32.389294,949.64922999999999
5.2779999999999996,3.2398932,2.4368560000000001,0.22677600000000001,32.834324000000002,949.62847999999997
5.3040000000000003,3.4573418999999999,2.4478922000000001,0.22796338999999999,35.324885999999999,949.70489999999995
5.33,3.3119277999999999,2.4339662,0.22636463000000001,33.637863000000003,949.43462999999997
5.3559999999999999,3.3859059999999999,2.4337903999999999,0.22634805999999999,34.410812,949.92908
5.3819999999999997,3.2780249000000001,2.4333700999999999,0.22647832000000001,33.272007000000002,949.74023
5.4080000000000004,3.3682512999999998,2.4367435,0.22686124999999999,34.172234000000003,949.57050000000004
5.4340000000000002,3.2748870999999999,2.4438241000000001,0.22768272000000001,32.956108,949.66150000000005
5.46,3.2606679999999999,2.4332978999999999,0.22657858,33.121689000000003,949.79558999999995
5.4859999999999998,3.2474449000000001,2.4339471000000001,0.22662421999999999,32.946930000000002,949.87054000000001
5.5119999999999996,3.2687819,2.4340329000000001,0.22672343,33.197463999999997,949.69426999999996
5.5380000000000003,3.1825271000000002,2.4338820000000001,0.22682308000000001,32.271178999999997,949.64733999999999
5.5640000000000001,3.2054578999999999,2.4393942000000002,0.22744954000000001,32.660217000000003,949.28931
5.59,3.1867429999999999,2.4321389,0.22664033,32.393616000000002,949.99505999999997
5.6159999999999997,3.2824732999999999,2.4366534,0.22712961000000001,33.323256999999998,949.71667000000002
5.6420000000000003,3.2708724,2.4314274999999999,0.22662857,33.249141999999999,950.48339999999996
5.6680000000000001,3.3010674,2.4329461999999999,0.22689047000000001,33.512371000000002,950.09429999999998
5.694,3.2966172999999999,2.4342206000000002,0.22712381000000001,33.348179000000002,949.90368999999998
5.72,3.1657877000000001,2.4296264999999999,0.22661465,32.142955999999998,949.98339999999996
5.7460000000000004,3.1426376999999999,2.4371060999999998,0.22722951999999999,31.902650999999999,949.84795999999994
5.7720000000000002,3.1978962000000002,2.4453166,0.22795713000000001,32.240082000000001,950.23784999999998
5.798,3.1190430999999998,2.430501,0.22670140999999999,31.686487,950.15581999999995
5.8239999999999998,3.1408339000000001,2.4282815000000002,0.22664989999999999,31.949086999999999,950.00347999999997
5.85,3.1370509000000002,2.4295654,0.22670212000000001,31.852914999999999,949.96765000000005
5.8760000000000003,3.1977359999999999,2.4376997999999999,0.22748344000000001,32.730465000000002,950.43682999999999
5.9020000000000001,3.4118949999999999,2.4292661999999998,0.22640167,33.239933000000001,950.16228999999998
5.9279999999999999,3.1699944000000002,2.4304668999999999,0.22674158,32.159519000000003,950.15832999999998
5.9539999999999997,3.2865362,2.4245119000000002,0.22610163999999999,33.304276000000002,950.05969000000005
5.98,3.2475847999999998,2.4279282000000002,0.22644276999999999,32.986977000000003,950.10455000000002
6.0060000000000002,3.3168869000000001,2.4355698000000001,0.22710948,33.557944999999997,950.32916
6.032,2.5097182,2.4396601000000002,0.22762980999999999,27.02422,950.32372999999995
6.0579999999999998,3.1917498000000002,2.4289204999999998,0.22644074,32.392924999999998,949.96716000000004
6.0839999999999996,3.138083,2.4179881000000001,0.22537552,31.890609999999999,950.13507000000004
6.11,3.2168801,2.4285692999999999,0.22634375000000001,32.662903,950.44635000000005
6.1360000000000001,3.1471694000000001,2.4366848000000001,0.22720000000000001,31.915572999999998,950.10766999999998
6.1619999999999999,3.7679338000000002,2.4489353,0.22843377000000001,38.827061,950.17278999999996
6.1879999999999997,3.1031566000000002,2.4291356,0.22637441999999999,31.504588999999999,950.07110999999998
6.2140000000000004,3.1963743999999998,2.4209282000000001,0.22550625999999999,32.491672999999999,950.26166000000001
6.24,3.1613684000000002,2.4286690000000002,0.22621514000000001,32.124676000000001,950.38440000000003
6.266,3.1491365,2.4365443999999998,0.22709857999999999,31.844732,950.05156999999997
6.2919999999999998,2.6967851999999999,2.4369790999999998,0.22698878,27.243289999999998,950.25707999999997
6.3179999999999996,3.1277883000000002,2.4288770999999998,0.22615652999999999,31.778751,950.25214000000005
6.3440000000000003,3.0500503000000001,2.4185481000000002,0.22511988999999999,30.986657999999998,950.32581000000005
6.37,3.1306020999999999,2.4287515000000002,0.22616822,31.817408,950.24010999999996
6.3959999999999999,3.1895771000000002,2.4347758000000002,0.22685899000000001,32.330643000000002,950.17987000000005
6.4219999999999997,3.6264395999999999,2.4420259,0.22739408999999999,36.748863,950.26653999999996
6.4480000000000004,3.0965240000000001,2.4290981,0.22614234999999999,31.415554,950.39116999999999
6.4740000000000002,3.2462304,2.4230125,0.22553533000000001,32.937187000000002,950.27459999999996
6.5,2.9972772999999999,2.4289162000000002,0.22610694000000001,30.405584000000001,950.10986000000003
6.5259999999999998,3.1816868999999999,2.4357603000000001,0.22689934,32.309089999999998,950.46178999999995
6.5519999999999996,2.7089783999999999,2.4448170999999999,0.22774701999999999,26.993492,950.19159000000002
6.5780000000000003,2.9857578,2.4300484999999998,0.22614281,30.320430999999999,950.22136999999998
6.6040000000000001,2.9554461999999999,2.4239956999999999,0.22545013,29.964174,950.21130000000005
6.63,3.0237984999999998,2.4316206,0.22626936,30.662154999999998,949.80902000000003
6.6559999999999997,3.0689633000000001,2.4365057999999999,0.22686310000000001,31.136773999999999,950.36847
6.6820000000000004,3.2548759,2.4480051999999999,0.22797285,33.321666999999998,950.23546999999996
6.7080000000000002,3.0547209,2.4316315999999998,0.22629915,31.037451000000001,951.05939000000001
6.734,3.2138772000000002,2.4295580000000001,0.22601806999999999,32.669449,950.10449000000006
6.76,3.1262691,2.4318892999999999,0.22627755999999999,31.746711999999999,950.29558999999995
6.7859999999999996,3.2038848,2.4369111000000001,0.22673061,32.564827000000001,950.03112999999996
6.8120000000000003,2.9435772999999998,2.4453743000000001,0.22771828999999999,29.47176,950.14624000000003
6.8380000000000001,3.0674538999999998,2.4324941999999998,0.22631867,31.164021000000002,950.08983999999998
6.8639999999999999,3.0489562000000001,2.4319723,0.22605425000000001,31.010462,950.40819999999997
6.89,3.0705409000000001,2.4350342999999999,0.22655927000000001,31.158557999999999,950.24041999999997
6.9160000000000004,3.0198716999999999,2.4370040999999998,0.22675334999999999,30.657463,950.02855999999997
6.9420000000000002,3.1564890999999999,2.4477549000000001,0.22792548000000001,32.271053000000002,950.61023
6.968,3.1242423000000001,2.4364328,0.22666074,31.712955000000001,950.11743000000001
6.9939999999999998,3.1739912000000001,2.4391034,0.22681855000000001,32.233635,950.16467
7.02,3.0452018000000001,2.4363522999999998,0.22662177999999999,30.902317,950.11333999999999
7.0460000000000003,3.0645254,2.4386872999999998,0.22680887999999999,31.155864999999999,950.01611000000003
7.0720000000000001,3.0643436999999998,2.4442501000000001,0.22750044,30.818598000000001,950.33459000000005
7.0979999999999999,3.0648512999999999,2.4355457,0.22652549,31.100328000000001,950.19
7.1239999999999997,2.9695279999999999,2.4384394,0.22689604999999999,30.087008999999998,950.00995
7.15,2.9550966999999999,2.4362607000000001,0.22673294999999999,30.031796,949.76868000000002
7.1760000000000002,2.9630125,2.4378096999999999,0.22678754000000001,30.084250999999998,950.33758999999998
7.202,2.9559481000000001,2.4397383000000001,0.22722168000000001,30.094486,950.12792999999999
7.2279999999999998,3.0397656,2.4377065,0.22674192000000001,30.873047,950.13824
7.2539999999999996,3.1595075000000001,2.4438856000000002,0.22734857,31.990535999999999,950.08051
7.28,2.9488108,2.4445945999999998,0.22727977999999999,30.072395,950.17102
7.306,2.9987854999999999,2.4383607,0.22701344000000001,30.440666,949.68480999999997
7.3319999999999999,3.0082974,2.4369729000000002,0.22691005,30.395275000000002,950.19323999999995
7.3579999999999997,2.9926720000000002,2.4370452999999999,0.22689815999999999,30.378080000000001,950.15575999999999
7.3840000000000003,3.0417461000000001,2.4441470999999999,0.22768870999999999,30.569739999999999,949.82275000000004
7.41,2.7887409000000001,2.4452357,0.22794840999999999,29.440595999999999,950.36139000000003
7.4359999999999999,2.9693892000000002,2.43642,0.22690474999999999,30.127006999999999,950.28887999999995
7.4619999999999997,2.8805939999999999,2.4300975999999999,0.22653703,29.249428000000002,950.43322999999998
7.4880000000000004,2.9103918000000002,2.4353680999999998,0.22685674,29.505537,950.32343000000003
7.5140000000000002,2.9434960000000001,2.4430114999999999,0.22773872000000001,30.029119000000001,950.52068999999995
7.54,3.5849559000000002,2.4398971,0.22716795000000001,34.672203000000003,950.79278999999997
7.5659999999999998,2.9854910000000001,2.4361649000000001,0.22709008,30.317948999999999,950.23461999999995
7.5919999999999996,3.0921447,2.4284393999999998,0.22631180000000001,31.303903999999999,950.33867999999995
7.6180000000000003,3.1462859999999999,2.4348630999999998,0.22706214999999999,31.859200000000001,949.81775000000005
7.6440000000000001,3.1150571999999999,2.4428128999999998,0.22785892999999999,31.633272000000002,950.38482999999997
7.67,2.2719629000000001,2.4474580000000001,0.22826560000000001,22.437023,950.45263999999997
7.6959999999999997,2.9184952000000002,2.4341004000000002,0.22704102000000001,29.594601000000001,950.89928999999995
7.7220000000000004,2.8792217,2.4236977,0.22605491999999999,29.268082,950.28156000000001
7.7480000000000002,2.9586760999999999,2.4342956999999998,0.22710021,30.017945999999998,950.32721000000004
7.774,2.9474776,2.4420747999999999,0.22804572000000001,29.964507999999999,951.02246000000002
7.8,3.3889811000000001,2.4483182000000001,0.22850910999999999,34.599257999999999,950.33887000000004
7.8259999999999996,2.8549131999999999,2.4344223,0.22710316,28.977900999999999,950.45105000000001
7.8520000000000003,3.0745241999999999,2.4252441,0.22615548999999999,31.229969000000001,950.20874000000003
7.8780000000000001,2.944782,2.4324110000000001,0.22687243000000001,29.881385999999999,950.44586000000004
7.9039999999999999,3.0139228999999998,2.4394181000000001,0.22768019,30.484196000000001,950.40746999999999
7.93,2.3591809000000001,2.4425321000000002,0.22781196000000001,24.101417999999999,949.92571999999996
7.9560000000000004,2.8850693999999999,2.4321511,0.22679457,29.301043,950.53441999999995
7.9820000000000002,2.8361773000000001,2.4235890000000002,0.22584224999999999,28.749420000000001,950.48779000000002
8.0079999999999991,2.8946432999999998,2.4331014,0.22688726000000001,29.382528000000001,950.43231000000003
8.0340000000000007,2.8051374,2.4388494000000001,0.22744383000000001,28.441524999999999,950.65423999999996
8.06,3.3240352,2.4507389000000002,0.22868983000000001,34.012912999999998,950.49096999999995
8.0860000000000003,2.8753264000000001,2.4329698,0.22678572,29.214502,950.80023000000006
8.1120000000000001,3.0688645999999999,2.4284804000000002,0.22619437000000001,31.151754,950.56646999999998
8.1379999999999999,2.8997087000000001,2.4323381999999998,0.22665362,29.459880999999999,950.27277000000004
8.1639999999999997,2.9273131000000001,2.4369211000000002,0.22719616000000001,29.753889000000001,950.48925999999994
8.19,2.5207693999999998,2.4449542000000002,0.2277547,25.075727000000001,950.46869000000004
8.2159999999999993,2.7682478000000001,2.4312699000000002,0.22650265999999999,28.068335000000001,950.40459999999996
8.2420000000000009,2.6374773999999999,2.4272740000000002,0.2258908,26.729696000000001,950.41436999999996
8.2680000000000007,2.7581427000000001,2.4331160000000001,0.22658363000000001,28.010411999999999,950.53992000000005
8.2940000000000005,2.7376355999999999,2.4353951999999999,0.22687304,27.767813,950.65637000000004
8.32,2.9672298000000001,2.4470595999999998,0.22818243999999999,30.325243,950.49170000000004
8.3460000000000001,2.8319421,2.4334137,0.22666325000000001,28.792774000000001,950.40967000000001
8.3719999999999999,2.9980183,2.43242,0.22643817999999999,30.441158000000001,950.60901000000001
8.3979999999999997,2.8184372999999998,2.4335227000000001,0.22665326,28.622692000000001,950.54705999999999
8.4239999999999995,2.8479163999999999,2.4369431000000001,0.22697046000000001,28.908232000000002,950.25494000000003
8.4499999999999993,2.7127810000000001,2.4455640000000001,0.22786467999999999,27.173151000000001,950.28638000000001
8.4760000000000009,2.7538418999999998,2.4329572000000002,0.22645994,27.887177999999999,950.28687000000002
8.5020000000000007,2.7757189000000002,2.4338848999999998,0.22650042000000001,28.146774000000001,950.38367000000005
8.5280000000000005,2.7519621999999999,2.4344820999999999,0.22660394,27.883807999999998,950.30913999999996
8.5540000000000003,2.7512797999999998,2.4361603000000001,0.22680636000000001,27.905334,950.23279000000002
8.58,2.8036919,2.4445686000000002,0.22781239,28.602699000000001,950.61725000000001
8.6059999999999999,2.7322017999999999,2.4340985000000002,0.22657019,27.780723999999999,950.51349000000005
8.6319999999999997,2.8585674999999999,2.4383259000000002,0.22699970999999999,29.059401000000001,950.29681000000005
8.6579999999999995,2.7399353999999998,2.4352033,0.22664566,27.842281,950.03876000000002
8.6839999999999993,2.8039963000000001,2.4377127000000001,0.22679751000000001,28.432199000000001,949.92291
8.7100000000000009,2.7122893000000001,2.4405985000000001,0.22725402,27.372924999999999,950.16516000000001
8.7360000000000007,2.6592311999999998,2.4359035000000002,0.22662516999999999,27.013646999999999,950.36310000000003
8.7620000000000005,2.6547991999999998,2.4411182,0.22706572999999999,27.037512,950.12714000000005
8.7880000000000003,2.5832614999999999,2.4419992000000001,0.22704989,26.116394,949.97766000000001
8.8140000000000001,2.7004410999999999,2.4382505000000001,0.22684222000000001,27.392061000000002,950.17719
8.84,2.7203390999999999,2.4389555000000001,0.22704827999999999,27.693363000000002,950.18231000000003
8.8659999999999997,2.7750802000000001,2.4381723000000002,0.22677551000000001,28.205535999999999,950.31244000000004
8.8919999999999995,2.7994241999999998,2.4452927,0.22756699999999999,28.545874000000001,950.14404000000002
8.9179999999999993,2.6261659000000002,2.4316298999999999,0.22620494999999999,26.434488000000002,949.99982
8.9440000000000008,2.7918615,2.4398091000000002,0.22702463000000001,28.372413999999999,950.21691999999996
8.9700000000000006,2.8505454000000001,2.4355931000000002,0.22662197000000001,28.821898000000001,949.99608999999998
8.9960000000000004,2.6794251999999998,2.4376888000000001,0.22674491999999999,27.198205999999999,949.71001999999999
9.0220000000000002,2.7797391,2.4454348000000001,0.22756224999999999,27.974712,949.63806
9.048,2.2391109,2.4371765000000001,0.22650371,24.703673999999999,949.93140000000005
9.0739999999999998,2.7407062,2.4396141,0.22701273999999999,27.718494,949.96478000000002
9.1,2.7005911,2.4316439999999999,0.22632279999999999,27.468836,949.90070000000003
9.1259999999999994,2.6484613000000001,2.4391202999999999,0.22691642000000001,26.831007,949.81744000000003
9.1519999999999992,2.6807973,2.4465965999999999,0.22778704999999999,27.157458999999999,949.93488000000002
9.1780000000000008,3.3112043999999998,2.4436537999999999,0.22710215,34.066471,949.29363999999998
9.2040000000000006,2.6553306999999999,2.4399416,0.22711326000000001,26.926621999999998,949.71320000000003
9.23,2.6670715999999999,2.4307821000000001,0.22622234999999999,27.035447999999999,949.70654000000002
9.2560000000000002,2.6465725999999998,2.4376034999999998,0.22691744999999999,26.855602000000001,949.98437999999999
9.282,2.6987345,2.4460475000000002,0.22781815999999999,27.279146000000001,949.83867999999995
9.3079999999999998,2.1295071000000001,2.4532916999999999,0.22870466,21.056761000000002,949.91943000000003
9.3339999999999996,2.6936686000000001,2.4377599000000001,0.22698905,27.372638999999999,949.80164000000002
9.36,2.6920869000000001,2.4275544,0.22604051,27.313457,949.84229000000005
9.3859999999999992,2.7801144,2.4386519999999998,0.22717735,28.236643000000001,949.40161000000001
9.4120000000000008,2.7108037,2.4451816000000002,0.22789127000000001,27.527138000000001,949.53857000000005
9.4380000000000006,3.2793614999999998,2.4539156000000002,0.22889978999999999,33.184269,949.72753999999998
9.4640000000000004,2.6392901000000002,2.4378443000000001,0.22722972999999999,26.788768999999998,950.00629000000004
9.49,2.7957559000000001,2.4301971999999998,0.22643751000000001,28.396215000000002,949.78290000000004
9.516,2.6633252999999999,2.4364164000000001,0.22708072000000001,27.004090999999999,949.87230999999997
9.5419999999999998,2.7781577,2.4423398999999999,0.22783336000000001,28.234276000000001,949.86986999999999
9.5679999999999996,2.2767021999999999,2.4485459000000001,0.22847851999999999,22.613878,949.80627000000004
9.5939999999999994,2.6357903,2.4355891000000001,0.22713847000000001,26.755291,949.96051
9.6199999999999992,2.6211680999999998,2.428261,0.22633159,26.576201999999999,950.07317999999998
9.6460000000000008,2.6004282999999999,2.4351530000000001,0.22716759,26.387878000000001,949.85033999999996
9.6720000000000006,2.5772200000000001,2.4387286000000001,0.22772919,26.224974,949.33258000000001
9.6980000000000004,2.8752827999999999,2.4505876999999998,0.22883178000000001,29.486533999999999,949.88959
9.7240000000000002,2.5863711999999999,2.4345880000000002,0.22708788999999999,26.227454999999999,949.79400999999996
9.75,2.7384517000000002,2.4317199999999999,0.22669776,27.762789000000001,950.45330999999999
9.7759999999999998,2.540451,2.4340218999999998,0.22698942,25.769272000000001,950.07672000000002
9.8019999999999996,2.7204328000000002,2.4379487000000002,0.22752138999999999,27.640034,949.92174999999997
9.8279999999999994,2.4211919000000002,2.4466429000000001,0.22841394000000001,24.144192,950.03679999999997
9.8539999999999992,2.5680765999999999,2.4334190000000002,0.22694859000000001,26.037085000000001,950.05182000000002
9.8800000000000008,2.5139813000000002,2.4305694,0.22651435,25.537775,950.21996999999999
9.9060000000000006,2.4982255000000002,2.4336782000000001,0.22696785999999999,25.357399000000001,949.71600000000001
9.9320000000000004,2.4812802999999999,2.4354440999999998,0.22717044,25.158246999999999,950.03583000000003
9.9580000000000002,2.6922288000000001,2.4455018000000002,0.22826524000000001,27.508707000000001,950.17651000000001
9.984,2.5719224999999999,2.4326786999999999,0.22682816,26.115618000000001,950.40935999999999
10.01,2.7880417999999998,2.4354637000000001,0.22697638000000001,28.245343999999999,950.39959999999996
10.036,2.6876557000000001,2.4330582999999999,0.22678819,27.237537,950.49774000000002
10.061999999999999,2.5852350999999998,2.4348369000000001,0.22695452999999999,26.219598999999999,950.2962
10.087999999999999,2.6933463,2.4419270000000002,0.22777836000000001,27.052454000000001,950.49145999999996
10.3514,2.5563791,2.4382286,0.22712684,25.861457999999999,950.68426999999997
10.8714,2.5251076000000001,2.4381100999999998,0.22713688000000001,25.633890000000001,950.76720999999998
11.391400000000001,2.4586070000000002,2.4407618000000002,0.22732978000000001,24.945271999999999,950.61406999999997
11.9114,2.4198393999999999,2.4393970999999999,0.2273107,24.560606,950.72429999999997
12.4314,2.3371846999999999,2.4368622000000002,0.22703846999999999,23.708199,950.93439000000001
12.9514,2.3023205,2.4365442000000002,0.22691736000000001,23.378316999999999,950.28612999999996
13.471399999999999,2.4392078000000001,2.4357633999999999,0.2268744,24.772051000000001,950.26500999999996
13.991400000000001,2.2244429999999999,2.4351772999999999,0.22684599,22.577708999999999,950.29796999999996
14.5114,2.1912189,2.4350429,0.22679732999999999,22.245418999999998,950.28710999999998
15.0314,2.2034574,2.4355755000000001,0.22676890999999999,22.353152999999999,950.51116999999999
15.551399999999999,2.2229179999999999,2.4354269999999998,0.22689866,22.554869,950.33240000000001
16.071400000000001,2.3626896999999998,2.4417564999999999,0.22747677999999999,23.682462999999998,950.48797999999999
16.5914,2.4126468000000001,2.4486534999999998,0.22818743999999999,24.502407000000002,950.32934999999998
17.1114,2.2997141000000001,2.4479655999999999,0.22815941000000001,23.415832999999999,949.98865000000001
17.631399999999999,2.1243767999999998,2.4402889999999999,0.22753762,21.613696999999998,949.96691999999996
18.151399999999999,2.1013025999999999,2.4328527000000002,0.22667224999999999,21.360287,950.41510000000005
18.671399999999998,2.1325368999999998,2.4322206999999998,0.22642358000000001,21.666844999999999,949.94848999999999
19.191400000000002,2.0791876,2.4355121,0.22678503,21.122727999999999,949.96880999999996
19.711400000000001,2.1545915999999998,2.4378943,0.22707430000000001,21.803460999999999,950.18268
20.231400000000001,2.1013467000000001,2.4406184999999998,0.22738747000000001,21.277291999999999,950.11719000000005
20.7514,2.1808686000000002,2.4394933999999999,0.22722475,22.099028000000001,950.39355
21.2714,2.083688,2.4386196,0.22719844,21.134041,950.22400000000005
21.791399999999999,2.0407112000000001,2.4378202,0.22715677000000001,20.712301,950.31757000000005
22.311399999999999,1.9872110000000001,2.4371277999999998,0.22697592,20.163451999999999,950.35064999999997
22.831399999999999,2.0517845000000001,2.4371044999999998,0.22696152,20.829799999999999,949.71545000000003
23.351400000000002,2.0324738,2.4362922,0.22697163000000001,20.648577,950.12450999999999
23.871400000000001,1.9898553999999999,2.4361459999999999,0.22693606,20.184249999999999,950.45477000000005
24.391400000000001,2.0518619999999999,2.4361419999999998,0.22687006000000001,20.832811,950.65381000000002
24.9114,1.9307797,2.4362803,0.22690371000000001,19.604837,950.49103000000002
25.4314,2.0426861999999999,2.4361655999999998,0.22695446,20.725014000000002,950.28216999999995
25.9514,1.9067725,2.4360642000000001,0.22690732999999999,19.361447999999999,950.21398999999997
26.471399999999999,1.9034545,2.4365230000000002,0.22690321999999999,19.298824,950.13085999999998
26.991399999999999,1.8691522,2.4380533999999998,0.22704877000000001,18.94153,949.96258999999998
27.511399999999998,1.8565978999999999,2.4374899999999999,0.22702953000000001,19.183699000000001,950.24976000000004
28.031400000000001,1.7044436999999999,2.4406188000000002,0.22729727999999999,17.429511999999999,950.28772000000004
28.551400000000001,1.6774175,2.4424043000000002,0.22743762000000001,16.988361000000001,949.93793000000005
29.071400000000001,1.8322921999999999,2.4471387999999998,0.22809191000000001,18.480715,950.26666
29.5914,1.8110364999999999,2.4438087999999998,0.22771295999999999,18.257444,950.13922000000002
30.1114,1.8473709,2.4441997999999998,0.22769755,18.609461,950.30700999999999
30.631399999999999,1.9610437000000001,2.4430915999999998,0.22765531,19.765909000000001,950.14813000000004
31.151399999999999,1.8540671,2.4407079,0.22749739999999999,18.716380999999998,950.06457999999998
31.671399999999998,1.9905747,2.4387796000000002,0.22725384000000001,20.138786,950.58605999999997
32.191400000000002,2.0076953999999998,2.4352437999999998,0.22682494,20.340755000000001,949.85875999999996
32.711399999999998,2.0499456,2.4322731000000002,0.22656514999999999,20.797501,949.81055000000003
33.231400000000001,2.1049888000000001,2.43207,0.22652628999999999,21.395533,949.67352000000005
33.751399999999997,2.0679276,2.4327679,0.22644712,21.032606000000001,950.11066000000005
34.2714,1.9743693,2.4341853000000002,0.22661775000000001,20.057936000000002,949.92296999999996
34.791400000000003,1.9803742,2.4376228000000002,0.22705565,20.152923999999999,950.41143999999997
35.311399999999999,1.8843349,2.4391017000000002,0.22721830000000001,19.122076,950.11803999999995
35.831400000000002,1.8511839000000001,2.4392097000000001,0.2271726,18.785332,950.36865
36.351399999999998,1.7982756,2.4387851,0.22723510999999999,18.236733999999998,950.31311000000005
36.871400000000001,1.8151089,2.4368018999999999,0.22705006999999999,18.415028,949.42296999999996
37.391399999999997,1.8756727,2.4363022000000001,0.22690418000000001,19.033750999999999,950.08496000000002
37.9114,1.878781,2.4349759,0.2267525,19.069551000000001,949.84636999999998
38.431399999999996,1.7301967,2.4337434999999998,0.22668524000000001,17.567169,949.74341000000004
38.9514,1.8458486999999999,2.4339054,0.22672585000000001,18.722193000000001,949.85875999999996
39.471400000000003,1.8193022999999999,2.4333974999999999,0.22656329,18.468755999999999,949.76031
39.991399999999999,1.735805,2.4336386000000001,0.22662483,17.621935000000001,950.00207999999998
40.511400000000002,1.7497596,2.4330053,0.22662674999999999,17.747313999999999,950.17345999999998
41.031399999999998,1.7319599000000001,2.4332446999999999,0.22663522,17.579837999999999,949.82494999999994
41.551400000000001,1.8332776,2.4331166999999998,0.22648649000000001,18.263344,949.85535000000004
42.071399999999997,1.8678998,2.4456376999999998,0.22787571000000001,19.016506,950.12798999999995
42.5914,1.7431004000000001,2.4435015,0.22773716999999999,17.77046,950.11974999999995
43.111400000000003,1.5857985999999999,2.4360141999999998,0.22694924,16.127825000000001,949.86346000000003
43.631399999999999,1.7655164000000001,2.4302030000000001,0.22626528000000001,17.906693000000001,950.06775000000005
44.151400000000002,1.7179632,2.4317340999999999,0.22641267000000001,17.410007,950.06317000000001
44.671399999999998,1.7580076,2.4361796,0.22692218,17.803328,950.10797000000002
45.191400000000002,1.8254786999999999,2.4373855999999998,0.22701028000000001,18.528853999999999,950.01984000000004
45.711399999999998,1.8101417,2.435317,0.22680052000000001,18.365637,949.90686000000005
46.231400000000001,1.8543818999999999,2.4339056000000001,0.22672744,18.813165999999999,949.86121000000003
46.751399999999997,1.7772281000000001,2.4327865000000002,0.2265866,18.058619,950.41570999999999
47.2714,1.8168526,2.4326493999999999,0.22649775,18.441761,950.31084999999996
47.791400000000003,1.7411455,2.4324295999999999,0.22654799,17.683439,950.13280999999995
48.311399999999999,1.6778006999999999,2.4314920999999998,0.22646953,17.021484000000001,949.87621999999999
48.831400000000002,1.7138625000000001,2.4326970999999999,0.22642966,17.368143,949.89635999999996
49.351399999999998,1.5097362000000001,2.4307653999999999,0.22624440000000001,15.650764000000001,950.07628999999997
49.871400000000001,1.6499007999999999,2.4434330000000002,0.22771759,16.646377999999999,950.23137999999994
50.391399999999997,1.7126806000000001,2.437789,0.22716940999999999,17.266611000000001,950.23748999999998
50.9114,1.7528900999999999,2.4315934000000001,0.22646503000000001,17.741631000000002,950.00323000000003
51.431399999999996,1.9090813,2.4282024,0.22606212000000001,19.392059,950.04552999999999
51.9514,1.8784726,2.4304120999999999,0.22632306999999999,19.089699,950.06970000000001
52.471400000000003,1.6696915999999999,2.4346757000000001,0.22669557000000001,16.991907000000001,950.20087000000001
52.991399999999999,1.8073391000000001,2.4361462999999999,0.22686779000000001,18.346474000000001,949.87225000000001
53.511400000000002,1.653187,2.4345150000000002,0.22679447999999999,16.785910000000001,949.68915000000004
54.031399999999998,1.7047257,2.4326745999999999,0.22661591,17.320065,950.07941000000005
54.551400000000001,1.6514580999999999,2.4309916,0.22633965,16.777971000000001,950.43511999999998
55.071399999999997,1.654339,2.4308239999999999,0.22632951000000001,16.784302,950.12598000000003
55.5914,1.7335011,2.4297423,0.22629580999999999,17.596582000000001,949.99982
56.111400000000003,1.6678563,2.4295716000000001,0.22626144000000001,16.946905000000001,949.91681000000005
56.631399999999999,1.6506928000000001,2.4295640000000001,0.22614678999999999,16.758022,949.84398999999996
57.151400000000002,1.7154282000000001,2.4292231000000002,0.22619860999999999,17.422279,950.11388999999997
57.671399999999998,1.6985479999999999,2.4289223999999998,0.22618687000000001,17.257625999999998,950.30547999999999
58.191400000000002,1.6964071000000001,2.4289540999999999,0.22609587,17.236889000000001,949.95885999999996
58.711399999999998,1.7097038,2.4292335999999999,0.22614350999999999,17.359755,949.96642999999995
59.231400000000001,1.7209848999999999,2.428858,0.22618324000000001,17.468015999999999,950.19934000000001
59.751399999999997,1.6359630000000001,2.4283201999999999,0.22614034999999999,16.613737,950.21416999999997
60.101399999999998,1.7088243999999999,2.4300815999999998,0.22617023,17.356190000000002,950.30731000000003