File: 3-1523-850C-02-60s.csv
Time,Force,Jaw,Strain,Stress,TC1
(sec),(kN),(mm),,(MPa),(C)
0,0.66091657000000004,1.6699289000000001E-3,0.000172,8.2175454999999999,849.47844999999995
2.5999999999999999E-2,0.70763171000000002,0.000356,0.000288,9.0065079000000008,849.40575999999999
5.1999999999999998E-2,0.60966050999999999,2.3000652000000001E-3,0.000009,7.5820751,849.69610999999998
7.8E-2,14.004530000000001,1.1373877999999999,9.8958656000000006E-2,161.26517000000001,850.86681999999996
0.104,14.884918000000001,2.0791947999999998,0.19030456000000001,156.73653999999999,854.05791999999997
0.13,13.313056,2.0862140999999998,0.19099313000000001,140.57786999999999,854.54944
0.156,12.494989,2.0849171000000002,0.19105991999999999,131.43259,854.76837
0.182,12.246995999999999,2.0846648000000001,0.19104840000000001,128.99628999999999,854.77936
0.20799999999999999,11.893689999999999,2.0844966999999999,0.19111948000000001,125.04055,854.58441000000005
0.23400000000000001,11.777312999999999,2.0852341999999999,0.19125171999999999,123.82576,854.42993000000001
0.26,11.421552999999999,2.0880782999999998,0.19158085999999999,121.03001,855.23784999999998
0.28599999999999998,11.62008,2.0848738999999998,0.19115457,122.16225,854.74377000000004
0.312,11.430104,2.0872483000000002,0.19133416,119.98251999999999,854.58527000000004
0.33800000000000002,11.514269000000001,2.0856523999999999,0.19116330000000001,121.13995,854.30920000000003
0.36399999999999999,11.432914999999999,2.0858843,0.19111191,120.28037999999999,853.98217999999997
0.39,11.729165,2.0884960000000001,0.19130876999999999,122.97987000000001,854.03314
0.41599999999999998,11.279681,2.0867460000000002,0.19110499,118.68438999999999,853.67908
0.442,11.348889,2.0873783000000001,0.19117896000000001,119.58848,853.75134000000003
0.46800000000000003,11.141946000000001,2.0870883,0.19107507000000001,117.14166,853.70354999999995
0.49399999999999999,11.058457000000001,2.0883672,0.19110133000000001,116.26285,853.92742999999996
0.52,10.786282999999999,2.0909466999999999,0.19121769,112.89136999999999,853.27966000000004
0.54600000000000004,11.018936999999999,2.0896678,0.19118914000000001,115.86803999999999,852.90917999999999
0.57199999999999995,10.843807,2.0926882999999998,0.19142671999999999,113.77091,852.69537000000003
0.59799999999999998,10.981007,2.0912682999999999,0.19120407,115.42193,852.27526999999998
0.624,10.906425,2.0927248000000001,0.19141074999999999,114.69949,851.8501
0.65,11.153159,2.0966733,0.19166800000000001,117.56988,852.02679000000001
0.67600000000000005,10.863358,2.0947781000000001,0.19156819999999999,114.18423,852.12243999999998
0.70199999999999996,11.017856,2.0964589,0.19172544999999999,116.03297000000001,852.44695999999999
0.72799999999999998,10.793977999999999,2.0953998999999999,0.19150876999999999,113.47063,851.24950999999999
0.754,10.820458,2.0957401,0.19169465999999999,113.77094,850.74572999999998
0.78,10.551126999999999,2.1002767000000002,0.19210182000000001,110.77948000000001,850.83063000000004
0.80600000000000005,10.805977,2.0963378000000001,0.19185959999999999,113.54226,850.66962000000001
0.83199999999999996,10.591203,2.0983684,0.19219111,111.00318,850.55768
0.85799999999999998,10.743418,2.0953534,0.19190579999999999,112.9931,850.52752999999996
0.88400000000000001,10.750809,2.0944840999999998,0.19190994,112.94628,850.50171
0.91,10.900378999999999,2.1015244000000002,0.19281267999999999,114.9623,849.99541999999997
0.93600000000000005,10.685969,2.0937073000000002,0.19208307999999999,112.30619,849.47717
0.96199999999999997,10.932508,2.0949651999999999,0.19217687999999999,115.07262,849.37720000000002
0.98799999999999999,10.699687000000001,2.0931875999999998,0.19203465,112.38251,849.04578000000004
1.014,10.695198,2.0929036000000001,0.19202699000000001,112.34922,848.66840000000002
1.04,10.524053,2.0992519999999999,0.19256077999999999,110.02473999999999,848.82434000000001
1.0660000000000001,10.681190000000001,2.0922577000000002,0.19181113,112.23636999999999,848.90990999999997
1.0920000000000001,10.448916000000001,2.0951404999999999,0.19214913,109.70585,848.92438000000004
1.1180000000000001,10.667994,2.0927810999999998,0.19177531,112.09036,848.79163000000005
1.1439999999999999,10.652718,2.0920844000000001,0.19162757999999999,111.98683,848.61499000000003
1.17,10.751439,2.1017128999999999,0.19263781999999999,113.25158999999999,848.41809000000001
1.196,10.674353999999999,2.0940793000000002,0.19179393,112.19987999999999,848.04827999999998
1.222,10.924652999999999,2.0957892,0.19186653000000001,114.83459999999999,847.89612
1.248,10.610147,2.094058,0.19167581,111.563,847.54138
1.274,10.619201,2.0961869000000002,0.19186829,111.58595,848.26275999999996
1.3,10.532344,2.1021101,0.19250271999999999,110.13753,847.96338000000003
1.3260000000000001,10.591238000000001,2.0958530999999998,0.19168372,111.27298999999999,847.67786000000001
1.3520000000000001,10.299991,2.1000073000000001,0.19206530999999999,108.20399999999999,847.53319999999997
1.3779999999999999,10.575513000000001,2.0989770999999999,0.19196029000000001,111.10328,847.52440999999999
1.4039999999999999,10.606121999999999,2.0987279000000001,0.19194628,111.44892,847.56464000000005
1.43,10.639457,2.1075594,0.19285898000000001,112.17592999999999,847.54449
1.456,10.488034000000001,2.1009774000000001,0.19217955,110.21507,847.80736999999999
1.482,10.794307999999999,2.1028283000000001,0.19235209,113.37045000000001,847.87531000000001
1.508,10.506271999999999,2.1012632999999998,0.19219168,110.44744,847.84893999999997
1.534,10.483136999999999,2.1007562000000002,0.19232535000000001,110.05601,847.84387000000004
1.56,10.359754000000001,2.1072142,0.19309304999999999,108.25072,847.56970000000001
1.5860000000000001,10.464615,2.0998177999999998,0.19240815999999999,109.93595999999999,847.27661000000001
1.6120000000000001,10.230147000000001,2.1019492,0.19264998999999999,107.4162,847.48163
1.6379999999999999,10.435117999999999,2.0996692000000001,0.19247993999999999,109.56004,847.56848000000002
1.6639999999999999,10.425045000000001,2.0988745999999998,0.19257485999999999,109.53187,847.48290999999995
1.69,10.597594000000001,2.107399,0.19353618,111.8263,847.79858000000002
1.716,10.382742,2.0984349,0.19250771,109.02048000000001,848.07403999999997
1.742,10.604277,2.0991647000000002,0.19259546999999999,111.38184,848.02251999999999
1.768,10.273286000000001,2.0979044,0.19249785999999999,107.92925,847.78850999999997
1.794,10.256779,2.0968976000000001,0.19236600000000001,107.73793999999999,847.73193000000003
1.82,10.035785000000001,2.1033814,0.19288930000000001,104.72196,847.41498000000001
1.8460000000000001,10.198759000000001,2.0967467000000002,0.19224820000000001,107.17237,848.18469000000005
1.8720000000000001,9.9078330999999995,2.0988788999999999,0.19228277999999999,104.11845,848.15454
1.8979999999999999,10.204179,2.0970084999999998,0.19206694999999999,107.18096,848.05646000000002
1.9239999999999999,10.229307,2.0962163999999999,0.19208989000000001,107.47862000000001,848.24512000000004
1.95,10.385999,2.1057500999999998,0.19289041000000001,109.562,848.12061000000006
1.976,10.144567,2.0978743999999998,0.19210279999999999,106.59751,847.86279000000002
2.0019999999999998,10.46965,2.0998323000000001,0.19233511,110.03016,848.00109999999995
2.028,10.131265000000001,2.0997531,0.19221332999999999,106.42204,848.13696000000004
2.0539999999999998,10.083377,2.1008467999999998,0.19224557,105.89841,848.36712999999997
2.08,9.8704262000000007,2.1077745000000001,0.19299458,102.93331999999999,848.44385
2.1059999999999999,10.110792,2.1014297000000002,0.19227345000000001,106.24141,848.88793999999996
2.1320000000000001,9.7695054999999993,2.1046946000000002,0.19257373,102.55717,848.70551
2.1579999999999999,9.9621934999999997,2.1034114000000002,0.19242196,104.57939,848.54199000000006
2.1840000000000002,9.9420976999999997,2.1031818000000002,0.19232289,104.48363999999999,848.21869000000004
2.21,10.155647,2.1129207999999999,0.19342234999999999,107.12828,848.42498999999998
2.2360000000000002,9.8527412000000005,2.1045964000000001,0.19256798999999999,103.44239,848.38726999999994
2.262,10.127468,2.1054656999999999,0.19270846,106.39077,848.42822000000001
2.2879999999999998,9.8168696999999998,2.1043322,0.19267434999999999,103.10947,848.78790000000004
2.3140000000000001,9.7853326999999997,2.1041002,0.19276345,102.7634,849.75201000000004
2.34,9.4096879999999992,2.1106148,0.19342490000000001,98.165893999999994,848.60046
2.3660000000000001,9.7212724999999995,2.1012113000000001,0.19258405000000001,102.09041000000001,848.44232
2.3919999999999999,9.4451847000000004,2.1032557000000001,0.19286065999999999,99.182922000000005,848.74950999999999
2.4180000000000001,9.7218952000000005,2.1022992,0.19275658000000001,102.08839999999999,849.01995999999997
2.444,9.7586718000000001,2.100498,0.19269924999999999,102.46727,849.15674000000001
2.4700000000000002,10.125235,2.1079995999999999,0.19349480999999999,106.4143,849.32848999999999
2.496,9.6874389999999995,2.1006825,0.19276615999999999,101.71436,849.30327999999997
2.5219999999999998,10.016769999999999,2.1012806999999998,0.19282057999999999,105.18607,849.39013999999997
2.548,9.6802577999999997,2.0993013,0.19258707999999999,101.61897,849.11273000000006
2.5739999999999998,9.6345262999999992,2.1003082000000002,0.19255549,101.19336,849.05957000000001
2.6,9.2292994999999998,2.1058252,0.19304565000000001,96.773124999999993,848.95483000000002
2.6259999999999999,9.6744909000000003,2.0987163,0.19229615999999999,101.62981000000001,848.90081999999995
2.6520000000000001,9.3373117000000008,2.1003029,0.19236353,98.113883999999999,849.06812000000002
2.6779999999999999,9.5470027999999996,2.0991928999999998,0.19235641000000001,100.27155999999999,849.42651000000001
2.7040000000000002,9.5754661999999993,2.0998952000000002,0.19235732999999999,100.53565,849.54858000000002
2.73,9.9978876000000003,2.1076427,0.1929891,104.99538,849.60040000000004
2.7559999999999998,9.5099772999999992,2.1004219000000002,0.19233884000000001,99.899215999999996,849.52277000000004
2.782,9.7837008999999995,2.1019714,0.19242123,102.72781000000001,849.50671
2.8079999999999998,9.4809827999999996,2.1022715999999999,0.19236341000000001,99.611153000000002,849.22217000000001
2.8340000000000001,9.4425316000000006,2.1029982999999999,0.19246645000000001,99.101189000000005,848.99890000000005
2.86,9.0005217000000002,2.1128203999999999,0.19349566000000001,94.436965999999998,849.97028
2.8860000000000001,9.4094666999999994,2.1037118000000001,0.19236848000000001,98.869118,849.72247000000004
2.9119999999999999,9.1438550999999997,2.1058222999999998,0.19259501000000001,96.055289999999999,849.61023
2.9380000000000002,9.4011068000000009,2.1049823999999999,0.19259749000000001,98.704834000000005,849.42719
2.964,9.3673991999999995,2.1054447000000001,0.19258565999999999,98.399085999999997,849.25391000000002
2.99,9.7840232999999994,2.1156899999999998,0.19367670000000001,102.73339,849.22307999999998
3.016,9.3627625000000005,2.1053369000000002,0.19268516999999999,98.314896000000005,849.23284999999998
3.0419999999999998,9.6632642999999998,2.1060938999999999,0.1928715,101.3873,849.52655000000004
3.0680000000000001,9.3109684000000001,2.1050539000000001,0.19286758000000001,97.716201999999996,849.64892999999995
3.0939999999999999,9.2748097999999999,2.1053834,0.19295913000000001,97.337508999999997,849.57439999999997
3.12,8.8146752999999993,2.1101179000000001,0.19350649,92.424194,849.53821000000005
3.1459999999999999,9.2665176000000002,2.1032945999999999,0.19295545,97.340416000000005,849.62408000000005
3.1720000000000002,8.9986467000000001,2.1033355999999999,0.19292936999999999,94.503860000000003,849.51184000000001
3.198,9.2652816999999992,2.1023934,0.19293624000000001,97.252037000000001,849.32848999999999
3.2240000000000002,9.2496805000000002,2.1010751999999999,0.19283248,97.211799999999997,849.19042999999999
3.25,9.6522617000000004,2.1074541,0.19335570999999999,101.3802,849.38946999999996
3.2759999999999998,9.2205305000000006,2.1016531000000001,0.19280547000000001,96.783173000000005,849.52874999999995
3.302,9.4733839,2.1014948000000002,0.19274144000000001,99.457290999999998,849.61046999999996
3.3279999999999998,9.2060776000000004,2.100733,0.19258691,96.730759000000006,849.74603000000002
3.3540000000000001,9.1618747999999997,2.1011166999999999,0.19261006999999999,96.217110000000005,849.81366000000003
3.38,8.7241259000000007,2.1066729999999998,0.19300044,91.549392999999995,849.59484999999995
3.4060000000000001,9.1416941000000005,2.1003790000000002,0.19243602000000001,96.010848999999993,848.50989000000004
3.4319999999999999,8.8958168000000004,2.1005292,0.19239827000000001,93.523026000000002,849.38373000000001
3.4580000000000002,9.1298075000000001,2.1019150999999998,0.19253867999999999,95.838593000000003,849.62341000000004
3.484,9.1408825,2.1009142000000001,0.19238234000000001,95.995070999999996,849.84514999999999
3.51,9.5593634000000005,2.1092064000000001,0.19311924,100.48059000000001,849.62621999999999
3.536,9.1264342999999997,2.1034731999999998,0.19262327000000001,95.839332999999996,849.57379000000003
3.5619999999999998,9.3990039999999997,2.1033843000000001,0.1924845,98.659782000000007,849.39606000000003
3.5880000000000001,9.0751200000000001,2.1042032000000002,0.19251899,95.339744999999994,849.35522000000003
3.6139999999999999,9.0447129999999998,2.1057727000000002,0.19267355,94.982071000000005,849.13788
3.64,8.6349192000000006,2.1163696999999999,0.19383234999999999,90.068222000000006,849.33911000000001
3.6659999999999999,9.0653763000000005,2.1050301,0.19256817000000001,95.176788000000002,849.61176
3.6920000000000002,8.7698029999999996,2.1060283000000002,0.19266184,92.092040999999995,849.82532000000003
3.718,9.0124797999999995,2.1073952,0.19284467,94.647582999999997,849.62938999999994
3.7440000000000002,9.0696610999999994,2.1068891999999999,0.19286851999999999,95.217224000000002,849.67058999999995
3.77,9.4677916,2.1181283,0.19403690000000001,99.504349000000005,849.48375999999996
3.7959999999999998,9.0276631999999992,2.1066394000000002,0.19291227999999999,94.770804999999996,849.40490999999997
3.8220000000000001,9.2810135000000002,2.1067955,0.19300903,97.423546000000002,849.34289999999999
3.8479999999999999,9.0084847999999997,2.1057904000000001,0.19299830000000001,94.566779999999994,849.29949999999997
3.8740000000000001,8.9826937000000004,2.1057826999999998,0.19312446,94.269690999999995,849.19353999999998
3.9,8.4918709000000003,2.1075900000000001,0.19321849999999999,88.677582000000001,849.51238999999998
3.9260000000000002,8.9693307999999998,2.1037330999999999,0.19301887000000001,94.159103000000002,849.60326999999995
3.952,8.7010983999999993,2.1019871000000001,0.19288469999999999,91.361519000000001,849.77117999999996
3.9780000000000002,8.9132566000000004,2.1027727000000001,0.19302327999999999,93.574164999999994,849.06812000000002
4.0039999999999996,8.9654789000000008,2.1025573999999998,0.19295865000000001,94.074532000000005,849.19385
4.03,9.4252967999999999,2.1052116999999999,0.19313414000000001,99.755508000000006,849.43407999999999
4.056,8.9212302999999995,2.1024761000000001,0.19279089999999999,93.631950000000003,849.57745
4.0819999999999999,9.1848679000000004,2.1022685000000001,0.19273059000000001,96.411582999999993,849.61712999999997
4.1079999999999997,8.9043273999999997,2.1010627999999998,0.19259024999999999,93.510124000000005,849.75201000000004
4.1340000000000003,8.9077921,2.1033892999999999,0.19274732,93.513367000000002,849.98852999999997
4.16,8.3912191000000007,2.1115197999999999,0.19355333999999999,87.172081000000006,849.48315000000002
4.1859999999999999,8.8865700000000007,2.1019777999999998,0.19263116,93.283957999999998,849.36774000000003
4.2119999999999997,8.6085004999999999,2.1026978000000001,0.19258367000000001,90.414291000000006,849.23224000000005
4.2380000000000004,8.8437023000000003,2.102427,0.19255713999999999,92.905097999999995,849.14227000000005
4.2640000000000002,8.8503761000000001,2.1036817999999999,0.19264011,93.008849999999995,849.31866000000002
4.29,9.3894166999999999,2.1086217999999999,0.19305605000000001,99.437683000000007,849.53003000000001
4.3159999999999998,8.8025379000000008,2.105248,0.19268703000000001,92.426940999999999,849.80078000000003
4.3419999999999996,9.0818615000000005,2.1052699000000001,0.19261940999999999,95.360778999999994,849.76868000000002
4.3680000000000003,8.8194789999999994,2.1062745999999999,0.19274380999999999,92.576042000000001,849.55047999999999
4.3940000000000001,8.7727251000000006,2.1079821999999999,0.19295935,92.039092999999994,849.53850999999997
4.42,8.1766672000000007,2.1100183000000001,0.19306481,84.930672000000001,849.28503000000001
4.4459999999999997,8.7361802999999991,2.1072524000000001,0.19279091000000001,91.749763000000002,849.11370999999997
4.4720000000000004,8.4993496000000004,2.1070587999999999,0.19282436,89.298400999999998,849.33630000000005
4.4980000000000002,8.6576920000000008,2.1087734999999999,0.19303676,90.875107,849.58123999999998
4.524,8.6752415000000003,2.1074888999999999,0.19298879999999999,91.097815999999995,849.59698000000003
4.55,9.2634744999999992,2.1120591000000002,0.19347839,97.890259,849.99927000000002
4.5759999999999996,8.6475715999999991,2.1077689999999998,0.19309947,90.762077000000005,849.16778999999997
4.6020000000000003,8.8851031999999996,2.106951,0.19310072,93.247512999999998,849.32690000000002
4.6280000000000001,8.5488958000000004,2.1049723999999999,0.19308728,89.793319999999994,849.33130000000006
4.6539999999999999,8.5532769999999996,2.1067078000000001,0.19329117000000001,89.788757000000004,849.39855999999997
4.68,7.9924808000000001,2.1066140999999998,0.19326755000000001,83.052695999999997,849.46893
4.7060000000000004,8.5022306000000007,2.1035103999999998,0.19305079,89.188384999999997,849.85706000000005
4.7320000000000002,8.2428550999999999,2.1013888999999999,0.19281599999999999,86.597031000000001,849.55957000000001
4.758,8.5084199999999992,2.1042654999999999,0.19308070999999999,89.341865999999996,849.71027000000004
4.7839999999999998,8.4929962000000003,2.1035194000000002,0.19298355,89.191467000000003,849.44421
4.8099999999999996,9.0327128999999999,2.1077143999999999,0.19329524000000001,95.616095999999999,849.34984999999995
4.8360000000000003,8.4285755000000009,2.1025621999999999,0.19279370000000001,88.467049000000003,848.95203000000004
4.8620000000000001,8.6949377000000005,2.1017386999999998,0.1925953,91.333304999999996,849.31524999999999
4.8879999999999999,8.3669232999999998,2.1022843999999998,0.19264055999999999,87.837692000000004,849.39508000000001
4.9139999999999997,8.3317365999999993,2.1032584000000001,0.19274421,87.437552999999994,849.67218000000003
4.9400000000000004,7.7515640000000001,2.1132247,0.19360778000000001,80.473952999999995,849.68884000000003
4.9660000000000002,8.3306217,2.1027516999999998,0.19257694,87.517982000000003,849.82494999999994
4.992,8.055377,2.1010962000000002,0.19229690999999999,84.610709999999997,849.61279000000002
5.0179999999999998,8.321949,2.1033819,0.19256382,87.420952,849.29796999999996
5.0439999999999996,8.3154143999999999,2.1047992999999998,0.19278322000000001,87.347426999999996,849.16772000000003
5.07,8.9137745000000006,2.1070351999999999,0.19267867999999999,94.352294999999998,849.20012999999994
5.0960000000000001,8.3201981000000007,2.1059258000000001,0.19269706,87.332427999999993,849.08947999999998
5.1219999999999999,8.5590401000000007,2.1050363000000001,0.19263047999999999,89.814423000000005,849.28223000000003
5.1479999999999997,8.2878485000000008,2.1074139999999999,0.19287343000000001,87.038871999999998,849.55078000000003
5.1740000000000004,8.3097963000000004,2.1083151999999998,0.19293025,87.191162000000006,849.80237
5.2,7.7037807000000003,2.1146194999999999,0.19349530000000001,79.991591999999997,849.59222
5.226,8.2887582999999996,2.1079354000000001,0.19288290999999999,87.000259,849.63122999999996
5.2519999999999998,8.0350751999999996,2.1068416000000001,0.19285221,84.43544,849.58130000000006
5.2779999999999996,8.2831563999999993,2.1074035000000002,0.19304184999999999,86.949707000000004,849.33123999999998
5.3040000000000003,8.2874622000000002,2.1079762,0.19314358000000001,87.018226999999996,849.05449999999996
5.33,8.9290657000000007,2.1146940999999999,0.19375002,92.600730999999996,849.91809000000001
5.3559999999999999,8.1633034000000002,2.1067195000000001,0.19315358999999999,85.698914000000002,849.88977
5.3819999999999997,8.4811601999999997,2.1044087,0.19298172999999999,88.986960999999994,849.62627999999995
5.4080000000000004,8.1992320999999997,2.1044526000000001,0.19313391999999999,86.018539000000004,849.33947999999998
5.4340000000000002,8.1657562000000006,2.1059060000000001,0.19334953999999999,85.668075999999999,849.15021000000002
5.46,7.4476199000000003,2.1014132000000001,0.19280699000000001,79.075089000000006,849.37030000000004
5.4859999999999998,8.2505684000000006,2.1031623000000002,0.19306000000000001,86.563805000000002,849.19672000000003
5.5119999999999996,7.9647535999999999,2.1013920000000001,0.19283407999999999,83.664955000000006,849.23821999999996
5.5380000000000003,8.1937943000000004,2.1031257999999999,0.19294675999999999,86.084534000000005,849.68658000000005
5.5640000000000001,8.2421226999999995,2.1024748999999998,0.19286159,86.567757,849.79864999999995
5.59,8.9125470999999994,2.1019041999999999,0.19265594,93.167991999999998,849.58471999999995
5.6159999999999997,8.1778010999999999,2.1036147999999999,0.19271983000000001,85.884888000000004,849.45770000000005
5.6420000000000003,8.4697475000000004,2.1016583,0.19250017,88.993233000000004,849.22942999999998
5.6680000000000001,8.1976309000000001,2.1023698,0.19266697999999999,86.123740999999995,849.24390000000005
5.694,8.1429004999999997,2.1041666999999999,0.19278893999999999,85.469275999999994,849.20794999999998
5.72,7.4809232000000003,2.1026039000000001,0.19243859999999999,80.051826000000005,849.46271000000002
5.7460000000000004,8.2072678000000003,2.1030502000000002,0.1926119,86.192299000000006,849.49041999999997
5.7720000000000002,7.9262442999999996,2.1018509999999999,0.19237024,83.351280000000003,849.57213999999999
5.798,8.1655215999999999,2.1055986999999998,0.19274995,85.764854,849.70421999999996
5.8239999999999998,8.2089148000000005,2.1061413,0.19280417,86.204291999999995,849.61499000000003
5.85,8.8403234000000008,2.1092875000000002,0.19297497999999999,92.024422000000001,849.56273999999996
5.8760000000000003,8.0624485000000004,2.1072446999999999,0.1927789,84.641250999999997,849.53003000000001
5.9020000000000001,8.3935145999999996,2.1070742999999998,0.19275011,88.123749000000004,849.34698000000003
5.9279999999999999,8.1028242000000006,2.1079862,0.19291306,85.034378000000004,849.66339000000005
5.9539999999999997,8.0534724999999998,2.1097712999999998,0.19308391,84.486343000000005,849.66840000000002
5.98,7.3002219000000004,2.1067355000000001,0.19274105,77.185210999999995,849.50989000000004
6.0060000000000002,8.1092081,2.1086504000000001,0.19303629,85.064209000000005,849.24890000000005
6.032,7.7972621999999996,2.1056192,0.19275543000000001,81.931647999999996,849.47028
6.0579999999999998,8.0016975000000006,2.1078708000000002,0.19313698000000001,83.989654999999999,849.21936000000005
6.0839999999999996,8.0609760000000001,2.1085948999999999,0.19325619999999999,84.642464000000004,849.09032999999999
6.11,8.8077878999999992,2.1133411,0.19371100999999999,91.130950999999996,849.23505
6.1360000000000001,8.0331907000000005,2.1055633999999999,0.19311871,84.315804,849.47906
6.1619999999999999,8.3292532000000001,2.1048469999999999,0.19311078000000001,87.469582000000003,849.50806
6.1879999999999997,8.0601214999999993,2.1053174000000001,0.19326761000000001,84.648955999999998,849.71929999999998
6.2140000000000004,8.0407095000000002,2.1054360999999999,0.19329894,84.328468000000001,849.88544000000002
6.24,7.3163876999999999,2.1029699000000002,0.19302152,78.249701999999999,849.41241000000002
6.266,8.0865822000000005,2.1037580999999999,0.19297880000000001,84.906386999999995,849.08916999999997
6.2919999999999998,7.8653792999999999,2.1011055000000001,0.19270253000000001,82.612105999999997,849.18853999999999
6.3179999999999996,8.0495253000000009,2.1031108000000001,0.19286422,84.516548,849.20483000000002
6.3440000000000003,8.0645571,2.1037024999999998,0.19288485,84.752403000000001,849.08667000000003
6.37,8.6909341999999992,2.1069102000000002,0.19309293999999999,89.247742000000002,849.29918999999995
6.3959999999999999,8.0847025000000006,2.1043099999999999,0.19282026999999999,84.904633000000004,849.4375
6.4219999999999997,8.3993997999999994,2.1010385,0.19250585000000001,88.174201999999994,849.45514000000003
6.4480000000000004,8.0843495999999995,2.1041154999999998,0.19281751999999999,84.865729999999999,849.67029000000002
6.4740000000000002,8.0064677999999994,2.1054976000000001,0.19295259000000001,84.011391000000003,849.63507000000004
6.5,7.3257570000000003,2.1002035000000001,0.19204056,78.784126000000001,849.23004000000003
6.5259999999999998,8.0500831999999996,2.1050011999999998,0.19269858000000001,84.511764999999997,849.02752999999996
6.5519999999999996,7.7825942000000001,2.1035295000000001,0.19253881,81.829750000000004,849.15326000000005
6.5780000000000003,7.9649706,2.1061285000000001,0.19276963,83.637482000000006,849.09045000000003
6.6040000000000001,8.0286179000000004,2.1076359999999998,0.19295543000000001,84.316032000000007,849.26520000000005
6.63,8.4158354000000006,2.1078834999999998,0.19279716999999999,86.330192999999994,849.58849999999995
6.6559999999999997,7.9838332999999997,2.1092371999999999,0.19298578999999999,83.823120000000003,849.91931
6.6820000000000004,8.2476138999999993,2.1075826000000002,0.19285324000000001,86.571731999999997,848.85015999999996
6.7080000000000002,7.9728928000000003,2.1083679000000002,0.19291269999999999,83.718108999999998,849.30804000000001
6.734,8.0148677999999993,2.1114731,0.19328901000000001,84.045738,849.22875999999997
6.76,7.3839234999999999,2.1122377000000001,0.19336502,79.420692000000003,849.24255000000005
6.7859999999999996,8.0500115999999995,2.1093495,0.19312288,84.472472999999994,849.63500999999997
6.8120000000000003,7.8431964000000001,2.1061668,0.19288981999999999,82.432404000000005,849.66021999999998
6.8380000000000001,8.0313902000000006,2.1084189000000002,0.19328238,84.286186000000001,849.58983999999998
6.8639999999999999,8.0419979000000001,2.1080849000000002,0.19333653000000001,84.400847999999996,849.52062999999998
6.89,8.6708622000000002,2.105356,0.19293241,89.142128,849.2124
6.9160000000000004,8.0496645000000004,2.1070441999999998,0.19340272,84.481255000000004,849.18102999999996
6.9420000000000002,8.289669,2.1044301999999999,0.19311618999999999,86.892905999999996,849.14948000000004
6.968,8.0026177999999994,2.1052233999999999,0.19320054,83.988960000000006,849.46149000000003
6.9939999999999998,8.0021962999999996,2.1063049,0.19333889000000001,83.934928999999997,849.41234999999995
7.02,7.5011926000000004,2.1090243000000002,0.19363113000000001,80.818686999999997,849.56457999999998
7.0460000000000003,7.9823526999999999,2.1035542,0.19299603000000001,83.804619000000002,849.79223999999999
7.0720000000000001,7.7597956999999997,2.1008656000000001,0.19258475,81.569962000000004,849.52562999999998
7.0979999999999999,7.9860654000000002,2.1043571999999999,0.19292955000000001,83.877082999999999,849.31688999999994
7.1239999999999997,8.0225544000000006,2.1057134,0.19305259,84.226996999999997,849.33318999999995
7.15,8.4376850000000001,2.1011023999999998,0.19238949999999999,86.464554000000007,849.25896999999998
7.1760000000000002,7.9697107999999997,2.1036975,0.19276929000000001,83.633774000000003,848.98859000000004
7.202,8.2410678999999991,2.1019309000000002,0.1926493,86.476401999999993,849.17719
7.2279999999999998,7.9845303999999997,2.1050558000000001,0.19281569000000001,83.865684999999999,850.11676
7.2539999999999996,7.9081554000000001,2.1068006000000001,0.19298642999999999,82.953002999999995,849.49927000000002
7.28,7.8167152,2.1009745999999998,0.19220544000000001,83.120330999999993,849.19042999999999
7.306,7.9438943999999996,2.1068342000000002,0.19285369999999999,83.419601,849.10802999999999
7.3319999999999999,7.7275305000000003,2.1045202999999999,0.19261835999999999,81.228836000000001,849.35828000000004
7.3579999999999997,7.9616503999999999,2.1085137999999999,0.19296613000000001,83.560164999999998,849.41241000000002
7.3840000000000003,8.0100365,2.1102916999999999,0.19307503000000001,84.070876999999996,849.40808000000004
7.41,7.9059743999999998,2.1147871,0.19361793999999999,82.511641999999995,849.62683000000004
7.4359999999999999,7.8983340000000002,2.1096922999999999,0.19310150000000001,82.897942,849.99481000000003
7.4619999999999997,8.1613340000000001,2.1075982999999998,0.1928629,85.59066,849.52562999999998
7.4880000000000004,7.8586330000000002,2.1097557999999998,0.19311175999999999,82.477585000000005,849.20361000000003
7.5140000000000002,7.8138956999999998,2.1121151,0.19342962,81.946288999999993,849.05389000000002
7.54,7.9064369000000001,2.1091856999999998,0.19315193999999999,83.142960000000002,849.17596000000003
7.5659999999999998,7.9358997000000002,2.1089950000000002,0.19323376,83.290619000000007,849.07219999999995
7.5919999999999996,7.6665124999999996,2.1066145999999999,0.19310221,80.587990000000005,849.91992000000005
7.6180000000000003,7.8294072000000003,2.1078722000000001,0.19330399000000001,82.204025000000001,849.48724000000004
7.6440000000000001,7.8689574999999996,2.1082797000000002,0.19349021,82.628387000000004,849.40930000000003
7.67,7.8551893000000002,2.1128768999999998,0.19373594,81.812256000000005,849.24829
7.6959999999999997,7.8530544999999998,2.1068560999999999,0.19342477999999999,82.397689999999997,848.92249000000004
7.7220000000000004,8.1028967000000005,2.1036679999999999,0.19310234000000001,85.038048000000003,849.09600999999998
7.7480000000000002,7.8618641,2.1053185000000001,0.19321827999999999,82.472610000000003,849.44763
7.774,7.8136124999999996,2.1081457000000001,0.19342595000000001,81.947815000000006,849.52814000000001
7.8,7.8700184999999996,2.1015462999999999,0.19283478000000001,82.812897000000007,849.69293000000005
7.8259999999999996,7.8376627000000001,2.1042383,0.19293234000000001,82.225623999999996,849.80798000000004
7.8520000000000003,7.6604285000000001,2.1024292,0.19274735000000001,80.542159999999996,849.56464000000005
7.8780000000000001,7.8326659000000003,2.1049918999999999,0.19294216,82.209541000000002,849.15075999999999
7.9039999999999999,7.8931880000000003,2.1059599000000002,0.1929469,82.944655999999995,849.20551
7.93,7.7563386000000003,2.1160239999999999,0.19387075000000001,81.504990000000006,849.23566000000005
7.9560000000000004,7.8863750000000001,2.1060903,0.19284894999999999,82.796143000000001,849.71301000000005
7.9820000000000002,8.1382971000000008,2.1037387999999999,0.19271542,85.248299000000003,849.51495
8.0079999999999991,7.8605670999999999,2.105896,0.19278181,82.553368000000006,849.27404999999999
8.0340000000000007,7.7861523999999998,2.1095166000000001,0.19321050000000001,81.633080000000007,849.22882000000004
8.06,7.8741279000000004,2.1108117000000002,0.19301178999999999,82.517204000000007,849.11432000000002
8.0860000000000003,7.8195642999999997,2.1085896000000002,0.19303396,82.076713999999996,848.82696999999996
8.1120000000000001,7.5914922000000002,2.1068449,0.19279826,79.836449000000002,849.06903
8.1379999999999999,7.7629184999999996,2.1099272,0.19308917,81.557570999999996,849.30798000000004
8.1639999999999997,7.9086432000000002,2.1124627999999999,0.19329755000000001,83.111755000000002,849.56835999999998
8.19,7.7980814000000001,2.1109219000000001,0.19327430000000001,81.910072,849.47906
8.2159999999999993,7.7960061999999999,2.1107985999999999,0.19318576000000001,81.825492999999994,849.52874999999995
8.2420000000000009,8.0431252000000004,2.1084480000000001,0.19302751000000001,84.269371000000007,849.39544999999998
8.2680000000000007,7.8395424,2.1106590999999999,0.19331607000000001,82.273781,849.26025000000004
8.2940000000000005,7.7475052,2.1127161999999999,0.19353366999999999,81.102585000000005,849.07781999999997
8.32,7.7829689999999996,2.1155574000000001,0.19361634999999999,81.629761000000002,849.41112999999996
8.3460000000000001,7.7886538999999999,2.1098572999999998,0.19342641999999999,81.765586999999996,849.53692999999998
8.3719999999999999,7.6110920999999996,2.1065345,0.19321087000000001,79.989754000000005,849.39855999999997
8.3979999999999997,7.7846484,2.1079245000000002,0.19345729,81.666602999999995,849.07781999999997
8.4239999999999995,7.8273701999999998,2.1095809999999999,0.19365341999999999,82.261107999999993,849.02752999999996
8.4499999999999993,7.7089930000000004,2.1166716000000001,0.19386845999999999,80.946785000000006,848.95830999999998
8.4760000000000009,7.7503580999999997,2.1065304,0.19343463,81.353012000000007,848.93944999999997
8.5020000000000007,7.9471506999999999,2.1049310999999999,0.19316791,83.251014999999995,849.07146999999998
8.5280000000000005,7.7469082,2.1064026,0.19329345000000001,81.357498000000007,849.26648
8.5540000000000003,7.6613631,2.1089818,0.19352342,80.262519999999995,849.40485000000001
8.58,7.7092767000000002,2.1034513000000001,0.19298792000000001,80.889763000000002,849.43628000000001
8.6059999999999999,7.6572766000000003,2.1048105000000001,0.19297636000000001,80.388382000000007,849.56835999999998
8.6319999999999997,7.5225530000000003,2.1038958999999999,0.19282025,79.204277000000005,849.27910999999995
8.6579999999999995,7.6963362999999996,2.1056168,0.1929855,80.796424999999999,848.89550999999994
8.6839999999999993,7.8064618000000001,2.1072259,0.19313628999999999,82.033241000000004,848.91431
8.7100000000000009,7.6827674000000004,2.1109140000000002,0.19316058999999999,80.596855000000005,848.94574
8.7360000000000007,7.7271643000000001,2.1069404999999999,0.19300735999999999,81.117835999999997,848.81371999999999
8.7620000000000005,7.9426332000000004,2.1051733000000001,0.19281108999999999,83.268332999999998,849.32312000000002
8.7880000000000003,7.6897054000000002,2.1076260000000002,0.19304925000000001,80.722899999999996,848.96465999999998
8.8140000000000001,7.5861139,2.1112676000000001,0.19320662,79.499870000000001,848.85137999999995
8.84,7.6702336999999998,2.1083744000000002,0.19298364000000001,80.534049999999993,848.98974999999996
8.8659999999999997,7.7046938000000003,2.1084928999999999,0.19301914000000001,80.923264000000003,848.75079000000005
8.8919999999999995,7.5322775999999996,2.1098542,0.19316089,79.201629999999994,848.93939
8.9179999999999993,7.6606344999999996,2.1112365999999998,0.19318376000000001,80.344893999999996,849.18469000000005
8.9440000000000008,7.7936864000000003,2.1137864999999998,0.19348467999999999,81.879363999999995,849.26648
8.9700000000000006,7.6450195000000001,2.1110989999999998,0.19317153000000001,80.229950000000002,849.39855999999997
8.9960000000000004,7.6625532999999999,2.1126657,0.19335943,80.317490000000006,849.47400000000005
9.0220000000000002,7.8693308999999996,2.1107776,0.19339671999999999,82.387755999999996,849.14075000000003
9.048,7.6332120999999997,2.1100091999999999,0.19331205000000001,80.143028000000001,848.90801999999996
9.0739999999999998,7.5250510999999998,2.1134206999999998,0.19371873000000001,78.918976000000001,848.96454000000006
9.1,7.6355494999999998,2.1100509000000001,0.19348583999999999,80.075637999999998,849.12183000000005
9.1259999999999994,7.6284647000000003,2.1083023999999999,0.1933658,80.035194000000004,849.03375000000005
9.1519999999999992,7.4884485999999999,2.1078236000000001,0.19350824999999999,78.736435,849.37347
9.1780000000000008,7.6441321000000002,2.1086349000000002,0.19350772999999999,80.196197999999995,849.04645000000005
9.2040000000000006,7.7797947000000001,2.1110692000000002,0.19387815999999999,81.654938000000001,849.08411000000001
9.23,7.5940485000000004,2.1064601000000001,0.1933994,79.693389999999994,849.01489000000004
9.2560000000000002,7.5922270000000003,2.1063556999999999,0.19336825999999999,79.748917000000006,848.97095000000002
9.282,7.7977961999999996,2.1070833000000002,0.19340943999999999,81.625122000000005,849.07970999999998
9.3079999999999998,7.6407394000000002,2.1059098000000001,0.19313194,80.204041000000004,849.35100999999997
9.3339999999999996,7.5440339999999999,2.1083634,0.19334129999999999,79.064682000000005,849.34607000000005
9.36,7.5850749000000004,2.1063097000000002,0.19311264,79.631073000000001,849.45770000000005
9.3859999999999992,7.5864419999999999,2.1062235999999999,0.19303809,79.709121999999994,849.45232999999996
9.4120000000000008,7.4735904,2.1055443,0.19302483000000001,78.651482000000001,849.27094
9.4380000000000006,7.5889039,2.1063193999999998,0.19297606,79.662727000000004,848.92125999999996
9.4640000000000004,7.6998835000000003,2.1099380999999999,0.19333144999999999,80.926276999999999,848.84698000000003
9.49,7.5646709999999997,2.1075908999999999,0.19310257,79.377525000000006,849.39606000000003
9.516,7.5770983999999997,2.1066296000000002,0.19289173000000001,79.548682999999997,849.70299999999997
9.5419999999999998,7.6662058999999996,2.1087710999999998,0.19318189,80.160033999999996,849.57183999999995
9.5679999999999996,7.5599002999999998,2.1091644999999999,0.19301729000000001,79.442290999999997,849.09393
9.5939999999999994,7.4573153999999997,2.1123954999999999,0.19339596000000001,78.077858000000006,849.09667999999999
9.6199999999999992,7.5155535000000002,2.1098710999999999,0.19312045,78.838333000000006,849.01404000000002
9.6460000000000008,7.5282625999999997,2.1103976000000002,0.19315539000000001,78.998711,848.93158000000005
9.6720000000000006,7.4435263000000003,2.1148188000000001,0.19372334999999999,78.344100999999995,849.47968000000003
9.6980000000000004,7.5295677000000003,2.1114533,0.19323573999999999,78.991005000000001,849.61803999999995
9.7240000000000002,7.6658583,2.1139440999999999,0.19348666,80.625359000000003,849.54705999999999
9.75,7.4795299000000002,2.1123712000000001,0.19337644000000001,78.466614000000007,849.60082999999997
9.7759999999999998,7.4898104999999999,2.1122689000000001,0.19344738,78.624450999999993,848.95543999999995
9.8019999999999996,7.5613003000000001,2.1127136000000002,0.19365399,78.990836999999999,849.07525999999996
9.8279999999999994,7.4628563000000003,2.1100669000000001,0.19343972000000001,78.283966000000007,849.44475999999997
9.8539999999999992,7.3085113000000002,2.1137700000000001,0.19381962999999999,76.378258000000002,849.52251999999999
9.8800000000000008,7.4830674999999998,2.1092938999999999,0.19342462999999999,78.506209999999996,849.47406000000001
9.9060000000000006,7.5310087000000001,2.1082165000000002,0.19336197999999999,79.040115,849.42664000000002
9.9320000000000004,7.4330287000000004,2.1110456000000002,0.19394195,78.215935000000002,849.21276999999998
9.9580000000000002,7.4575930000000001,2.1076039999999998,0.19352542,78.264449999999997,849.14612
9.984,7.6596679999999999,2.1088828999999998,0.19370235999999999,80.708350999999993,849.02881000000002
10.01,7.4535818000000003,2.1062284,0.19332346,78.231482999999997,849.08849999999995
10.036,7.4088782999999996,2.1066362999999999,0.19332870999999999,77.722060999999997,849.84862999999996
10.061999999999999,7.4623337000000003,2.1098157999999998,0.19370787,77.933623999999995,849.45050000000003
10.087999999999999,7.4202051000000004,2.105191,0.19307202000000001,77.923027000000005,848.99956999999995
10.3514,7.4873365999999999,2.1094941999999999,0.19335614000000001,78.444336000000007,849.12414999999999
10.8714,7.3772992999999998,2.1122877999999998,0.19362283999999999,77.114563000000004,849.26275999999996
11.391400000000001,7.1363449000000001,2.1085265,0.19321442,74.912368999999998,849.03747999999996
11.9114,7.0695205000000003,2.1086979000000001,0.19317703999999999,74.195037999999997,849.06859999999995
12.4314,6.9724292999999999,2.1081998,0.19320657999999999,73.177436999999998,849.31615999999997
12.9514,6.9633050000000001,2.1081998,0.19319792,73.078727999999998,849.50079000000005
13.471399999999999,6.9885739999999998,2.1089837999999999,0.19323546,73.352242000000004,849.69597999999996
13.991400000000001,6.8825855000000002,2.1083419000000001,0.19325297999999999,72.220298999999997,848.94006000000002
14.5114,6.7808032000000003,2.1084018000000002,0.19325981,71.166313000000002,848.96094000000005
15.0314,6.7300424999999997,2.1084645000000002,0.19318774,70.636070000000004,849.13244999999995
15.551399999999999,6.7159820000000003,2.1083088000000001,0.19317630999999999,70.480103,849.51111000000003
16.071400000000001,6.6985020999999998,2.1081222999999998,0.19323197,70.336014000000006,849.40679999999998
16.5914,6.6763678000000004,2.1089267999999999,0.19324730000000001,70.082038999999995,849.10883000000001
17.1114,6.6431269999999998,2.1086866999999998,0.19320139,69.737319999999997,849.36108000000002
17.631399999999999,6.6044035000000001,2.1090629000000001,0.19330755999999999,69.341071999999997,849.87750000000005
18.151399999999999,6.6010795,2.1096857,0.19338111999999999,69.317909,849.79492000000005
18.671399999999998,6.6212486999999998,2.1109531000000001,0.19344045000000001,69.526580999999993,849.51116999999999
19.191400000000002,6.6219811000000002,2.1098804000000002,0.19339812000000001,69.565513999999993,849.47717
19.711400000000001,6.6317244000000004,2.1095738000000002,0.19337362,69.564269999999993,849.48803999999996
20.231400000000001,6.5901307999999998,2.1081002,0.19312756,69.117797999999993,849.28461000000004
20.7514,6.4905438000000002,2.1087151,0.19328113,67.995743000000004,849.31371999999999
21.2714,6.3498711999999999,2.1118258999999999,0.19364022,66.429992999999996,849.41010000000006
21.791399999999999,6.1706829000000001,2.1154109999999999,0.19386929,64.577781999999999,849.39246000000003
22.311399999999999,6.2682962,2.1098005999999998,0.19327949999999999,66.207901000000007,849.33452999999997
22.831399999999999,6.2724981,2.1079674000000002,0.19321458,65.84272,849.50567999999998
23.351400000000002,6.2436971999999997,2.1079194999999999,0.19316085,65.547156999999999,850.07097999999996
23.871400000000001,6.2335824999999998,2.1076991999999999,0.19310118000000001,65.443291000000002,849.70050000000003
24.391400000000001,6.2383388999999996,2.1073309999999998,0.19313607999999999,65.482123999999999,849.49383999999998
24.9114,6.1686968999999996,2.1076412000000002,0.19319889000000001,64.752387999999996,849.26171999999997
25.4314,6.1423635000000001,2.107774,0.19312774999999999,64.484459000000001,848.83141999999998
25.9514,6.1120229000000004,2.1082801999999998,0.19326825,64.133385000000004,849.41168000000005
26.471399999999999,6.0468903000000003,2.1089400999999999,0.19332754999999999,63.434151,849.06604000000004
26.991399999999999,5.9668102000000003,2.1092954000000002,0.19325629999999999,62.563042000000003,849.10637999999994
27.511399999999998,5.9889811999999996,2.1068354,0.19300975000000001,62.906967000000002,849.24712999999997
28.031400000000001,6.0062617999999999,2.1064992,0.19311434,63.101582000000001,849.65704000000005
28.551400000000001,6.1131400999999999,2.1124293999999999,0.19363891,64.279990999999995,850.08405000000005
29.071400000000001,6.2132759000000002,2.1156182000000001,0.19385995,65.082229999999996,850.10913000000005
29.5914,5.9086889999999999,2.1071016999999999,0.19312572,62.041477,849.61053000000004
30.1114,5.8930492000000001,2.1061165000000002,0.19301227000000001,61.839511999999999,849.21447999999998
30.631399999999999,5.9136777,2.1064951000000001,0.19299018000000001,62.080531999999998,849.05498999999998
31.151399999999999,5.8549037000000004,2.1055326000000001,0.19296193,61.467753999999999,849.48883000000001
31.671399999999998,5.8124294000000001,2.1057568,0.19300885000000001,61.027779000000002,849.39313000000004
32.191400000000002,5.7931565999999997,2.1058264000000002,0.19294769000000001,60.840617999999999,849.95849999999996
32.711399999999998,5.8379712000000001,2.1068137,0.19304946000000001,61.313274,849.87829999999997
33.231400000000001,5.8064070000000001,2.1077157999999998,0.19319431000000001,60.992953999999997,849.63720999999998
33.751399999999997,5.8286876999999997,2.1074397999999999,0.19307606999999999,61.250205999999999,849.39599999999996
34.2714,5.8142671999999997,2.1051457,0.19283162000000001,60.994864999999997,849.65062999999998
34.791400000000003,5.7117939,2.1051109000000001,0.19295772999999999,59.868766999999998,849.62018
35.311399999999999,5.5287547000000004,2.1079156000000001,0.19319249999999999,57.858673000000003,849.42498999999998
35.831400000000002,5.3805560999999997,2.1102223000000002,0.19332073999999999,56.335628999999997,849.93822999999998
36.351399999999998,5.4609779999999999,2.1052963999999998,0.19293432999999999,57.763165000000001,849.31890999999996
36.871400000000001,5.5220264999999999,2.1045194,0.19285548,57.975769,850.03607
37.391399999999997,5.5064659000000002,2.1042074999999998,0.19273757999999999,57.827866,849.94
37.9114,5.4471826999999999,2.1041306999999998,0.19280628999999999,57.185023999999999,849.65252999999996
38.431399999999996,5.4306726000000003,2.1037425999999999,0.19278202999999999,57.035415999999998,849.57483000000002
38.9514,5.4772577,2.104409,0.19276642999999999,57.517631999999999,849.79852000000005
39.471400000000003,5.3809985999999999,2.1038814000000001,0.19273167999999999,56.503993999999999,849.73157000000003
39.991399999999999,5.1519537,2.1031528000000002,0.19273297,54.089111000000003,849.77472
40.511400000000002,5.1253963000000002,2.1034771999999999,0.19270166999999999,53.811024000000003,850.04840000000002
41.031399999999998,5.0820240999999999,2.1034636,0.19268948,53.331242000000003,850.13171
41.551400000000001,5.1191744999999997,2.1038443999999998,0.19280416,53.716960999999998,849.64202999999998
42.071399999999997,5.0671935000000001,2.1044223,0.19282845000000001,53.131813000000001,849.50549000000001
42.5914,5.0352611999999999,2.1044252000000001,0.19276309,52.80603,850.07354999999995
43.111400000000003,4.9744333999999997,2.1032796,0.19271331999999999,52.16283,849.75109999999995
43.631399999999999,4.9401587999999999,2.103224,0.19270118999999999,51.881259999999997,850.15332000000001
44.151400000000002,5.0272059000000002,2.1014674000000002,0.19245673999999999,52.842834000000003,849.48676
44.671399999999998,5.0186666999999998,2.1005001000000001,0.19241214000000001,52.776187999999998,850.22375
45.191400000000002,4.9976000999999997,2.1003387,0.1924544,52.567183999999997,849.47473000000002
45.711399999999998,5.0363645999999997,2.1024003000000002,0.19260803000000001,53.023617000000002,849.64739999999995
46.231400000000001,5.0634408000000004,2.1044117999999998,0.19285123000000001,53.300789000000002,849.92389000000003
46.751399999999997,5.1016579000000002,2.1065927000000002,0.19313369999999999,53.701447000000002,849.87707999999998
47.2714,5.2153071999999998,2.1061049000000001,0.19294579000000001,54.893177000000001,849.98168999999996
47.791400000000003,5.2251877999999996,2.1112015,0.19345459000000001,54.912052000000003,849.60686999999996
48.311399999999999,5.2334819000000001,2.1099274000000001,0.1934071,54.885413999999997,849.84662000000003
48.831400000000002,5.2056623000000002,2.105969,0.19292845,54.326424000000003,849.93604000000005
49.351399999999998,5.0392612999999997,2.1004220999999998,0.19231459000000001,52.508544999999998,849.88049000000001
49.871400000000001,4.9340967999999998,2.1022078999999998,0.19257362,51.834811999999999,850.16674999999998
50.391399999999997,4.9327598000000004,2.1003186999999999,0.19241892999999999,51.805328000000003,849.71405000000004
50.9114,4.9623828000000003,2.1004713000000002,0.19237161999999999,52.125286000000003,849.97082999999998
51.431399999999996,4.8887548000000001,2.0997678999999998,0.19234404999999999,51.352595999999998,849.63342
51.9514,4.8290663,2.0998193999999999,0.19238915000000001,50.729301,849.79395
52.471400000000003,4.9164529000000003,2.0998649999999999,0.192306,51.659843000000002,849.90319999999997
52.991399999999999,4.8445301000000001,2.0998223,0.19232985,50.885821999999997,849.75121999999999
53.511400000000002,4.8159350999999999,2.0992392999999998,0.19232836,50.597777999999998,849.92926
54.031399999999998,4.8104715000000002,2.0995268999999999,0.19230354999999999,50.537726999999997,849.22852
54.551400000000001,4.8465328000000003,2.0995452000000001,0.19229110999999999,50.936737000000001,849.90075999999999
55.071399999999997,4.8128848,2.0991428000000001,0.19232378999999999,50.575297999999997,849.96594000000005
55.5914,4.7752438000000001,2.0993952999999999,0.19230357000000001,50.189785000000001,849.58429000000001
56.111400000000003,4.7966318000000001,2.0995935999999999,0.19226341999999999,50.403305000000003,849.99329
56.631399999999999,4.7972840999999997,2.0992850999999999,0.19231899,50.397022,850.07996000000003
57.151400000000002,4.7745137,2.0998895000000002,0.19239379000000001,50.206511999999996,849.56641000000002
57.671399999999998,4.7553210000000004,2.1003120000000002,0.19232373,49.996974999999999,849.64490000000001
58.191400000000002,4.7433342999999999,2.1003159999999998,0.19241332999999999,49.902968999999999,849.69299000000001
58.711399999999998,4.8325763000000004,2.1000838000000002,0.19239286999999999,50.802204000000003,850.15070000000003
59.231400000000001,4.7970842999999999,2.0994112,0.19226842,50.342509999999997,850.17516999999998
59.751399999999997,4.7365556,2.0986419000000001,0.19220809999999999,49.672096000000003,849.49267999999995
60.101399999999998,4.5953732,2.0980772999999999,0.19223926999999999,48.382389000000003,849.77759000000003